Workbook

Sheet Generic
B1: 46113 | X1: Earnings | AG1: Deductions
A2: Employee ID | B2: Employee Name | C2: Gender | D2: UAN | E2: Bank Name | F2: Bank Account # | G2: Bank IFSC Code | H2: City | I2: Days in month | J2: Days of Pay | K2: Opening Leave Balance | L2: Eligible Leaves | M2: Leaves Availed | N2: Loss of Pay Days | O2: Closing Leave Balance | P2: Payable Days | Q2: Basic + DA | R2: HRA | S2: Medical allowance | T2: Conveyance | U2: Individual Performance Incentive | V2: Company Performance Incentive | W2: Total Fixed Salary | X2: Payable Basic + DA | Y2: Payable HRA | Z2: Payable Medical Allowance | AA2: Payable Conveyance | AB2: Individual Performance Incentive | AC2: Company Performance Incentive | AD2: Salary Loan availed this month | AE2: Other Arrears / Incentives | AF2: Bonus Accrued | AG2: Provident Fund (PF) | AH2: Professional Tax (PT) | AI2: Employees' State Insurance (ESI) | AJ2: Loan EMI | AK2: Total Additions | AL2: Total Deductions | AM2: Total Salary | AN2: Payable Salary | AO2: Employer contribution to ESI | AP2: Employer contribution to PF | AQ2: Gratuity | AR2: Total CTC | AS2: Previous Loan Balance | AT2: Closing Loan Balance | AU2: Tax Deduction on Source (TDS) | AV2: Annual Bonus | AW2: Cumulative TDS for this FY | AX2: Remarks | AY2: Loan repayment outside Salary | AZ2: Active (Y/N)
A3: 1 | B3: Saumya R Rao | C3: F | D3: 101898706542 | E3: HDFC Bank | F3: 12691870000226 | G3: HDFC0001269 | I3: 30 | J3: 30 | K3: 8 | L3: 3 | M3: 0 | N3: 0 | O3: 11 | P3: 30 | Q3: 30000 | R3: 15000 | S3: 7500 | T3: 7500 | U3: 0 | V3: 40000 | W3: 100000 | X3: 30000 | Y3: 15000 | Z3: 7500 | AA3: 7500 | AC3: 32000 | AF3: 0 | AG3: 1800 | AH3: 300 | AI3: 0 | AK3: 92000 | AL3: 2100 | AM3: 89900 | AN3: 89900 | AO3: 0 | AP3: 1800 | AQ3: 1443 | AR3: 95243 | AS3: 0 | AT3: 0 | AV3: 0 | AY3: 0 | AZ3: Y
A4: 2 | B4: Kiran Sham Khandige | C4: M | D4: 100193986476 | E4: ICICI bank | F4: 001401514208 | G4: ICIC0000014 | I4: 30 | J4: 30 | K4: 8 | L4: 3 | M4: 0 | N4: 0 | O4: 11 | P4: 30 | Q4: 30000 | R4: 15000 | S4: 7500 | T4: 7500 | U4: 0 | V4: 40000 | W4: 100000 | X4: 30000 | Y4: 15000 | Z4: 7500 | AA4: 7500 | AC4: 32000 | AF4: 0 | AG4: 1800 | AH4: 300 | AI4: 0 | AK4: 92000 | AL4: 2100 | AM4: 89900 | AN4: 89900 | AO4: 0 | AP4: 1800 | AQ4: 1443 | AR4: 95243 | AS4: 0 | AT4: 0 | AV4: 0 | AY4: 0 | AZ4: Y
A5: 1001 | B5: Dinesh | C5: M | D5: 101404270926 | E5: Kotak Mahindra Bank | F5: 1113584104 | G5: KKBK0007937 | I5: 30 | J5: 30 | K5: 0.5 | L5: 3 | M5: 1.5 | N5: 0 | O5: 2 | P5: 30 | Q5: 15000 | R5: 3540 | S5: 1180 | T5: 1180 | U5: 3323 | V5: 3323 | W5: 27546 | X5: 15000 | Y5: 3540 | Z5: 1180 | AA5: 1180 | AD5: 0 | AF5: 2277 | AG5: 1800 | AH5: 0 | AI5: 156.75 | AJ5: 28000 | AK5: 23177 | AL5: 29956.75 | AM5: -6779.75 | AN5: 18267 | AO5: 679.25 | AP5: 1950 | AQ5: 721.5 | AR5: 26527.75 | AS5: 171000 | AT5: 143000 | AV5: 27324 | AY5: 0 | AZ5: Y
A6: 1006 | B6: Rakshita Salyan | C6: F | D6: 101404270893 | E6: Kotak Mahindra Bank | F6: 1113586177 | G6: KKBK0007937 | I6: 30 | J6: 30 | K6: 1.5 | L6: 4 | M6: 1.5 | N6: 0 | O6: 4 | P6: 30 | Q6: 15000 | R6: 3540 | S6: 1180 | T6: 1180 | U6: 4368 | V6: 4368 | W6: 29636 | X6: 15000 | Y6: 3540 | Z6: 1180 | AA6: 1180 | AD6: 0 | AF6: 2390 | AG6: 1800 | AH6: 0 | AI6: 156.75 | AJ6: 0 | AK6: 23290 | AL6: 1956.75 | AM6: 21333.25 | AN6: 47623 | AO6: 679.25 | AP6: 1950 | AQ6: 721.5 | AR6: 26640.75 | AS6: 0 | AT6: 0 | AV6: 28680 | AY6: 0 | AZ6: Y
A7: 1024 | B7: Dishanth D | C7: M | D7: 101818017017 | E7: Kotak Mahindra Bank | F7: 3948638977 | G7: KKBK0007937 | I7: 30 | J7: 30 | K7: 1 | L7: 3 | M7: 0.5 | N7: 0 | O7: 3.5 | P7: 30 | Q7: 15000 | R7: 3388 | S7: 1796 | T7: 796 | U7: 900 | V7: 900 | W7: 22780 | X7: 15000 | Y7: 3388 | Z7: 1796 | AA7: 796 | AF7: 1823 | AG7: 1800 | AH7: 0 | AI7: 157.35 | AJ7: 0 | AK7: 22803 | AL7: 1957.35 | AM7: 20845.65 | AN7: 40899 | AO7: 681.85 | AP7: 1800 | AQ7: 721.5 | AR7: 26006.35 | AS7: 0 | AT7: 0 | AV7: 21876 | AY7: 0 | AZ7: Y
A8: 1028 | B8: Veeralakshmi R | C8: F | D8: 101768643043 | E8: HDFC Bank | F8: 50100454812858 | G8: HDFC0003699 | K8: 0 | L8: 0 | M8: 0 | N8: 0 | O8: 0 | P8: 0 | Q8: 0 | R8: 0 | S8: 0 | T8: 0 | U8: 0 | V8: 0 | W8: 0 | X8: 0 | Y8: 0 | Z8: 0 | AA8: 0 | AB8: 0 | AC8: 0 | AD8: 0 | AE8: 0 | AF8: 0 | AG8: 0 | AH8: 0 | AI8: 0 | AJ8: 0 | AK8: 0 | AL8: 0 | AM8: 0 | AN8: 0 | AO8: 0 | AP8: 0 | AQ8: 0 | AR8: 0 | AS8: 0 | AT8: 0 | AV8: 0 | AY8: 0 | AZ8: N
A9: 1030 | B9: Sushmitha Shetty | C9: F | D9: 101657750048 | E9: Bank of Baroda | F9: 82010100004480 | G9: BARB0VJKARK | I9: 30 | J9: 30 | K9: 2.5 | L9: 3.5 | M9: 5.5 | N9: 0 | O9: 0.5 | P9: 30 | Q9: 15000 | R9: 3540 | S9: 1180 | T9: 1180 | U9: 5289 | V9: 5289 | W9: 31478 | X9: 15000 | Y9: 3540 | Z9: 1180 | AA9: 1180 | AF9: 0 | AG9: 1800 | AH9: 0 | AI9: 156.75 | AK9: 20900 | AL9: 1956.75 | AM9: 18943.25 | AN9: 18943 | AO9: 679.25 | AP9: 1800 | AQ9: 721.5 | AR9: 24100.75 | AS9: 0 | AT9: 0 | AV9: 0 | AY9: 0 | AZ9: Y
A10: 1031 | B10: Gururaj Shet | C10: M | D10: 101767120465 | E10: Karnataka Bank | F10: 4782500102104101 | G10: KARB0000478 | I10: 30 | J10: 30 | K10: 0 | L10: 3 | M10: 1 | N10: 0 | O10: 2 | P10: 30 | Q10: 15000 | R10: 9000 | S10: 8000 | T10: 3000 | U10: 6000 | V10: 6000 | W10: 47000 | X10: 15000 | Y10: 9000 | Z10: 8000 | AA10: 3000 | AB10: 7200 | AC10: 4800 | AE10: 4000 | AG10: 1800 | AH10: 300 | AI10: 0 | AK10: 51000 | AL10: 2100 | AM10: 48900 | AN10: 48900 | AO10: 0 | AP10: 1800 | AQ10: 721.5 | AR10: 53521.5 | AS10: 0 | AT10: 0 | AV10: 0 | AY10: 0 | AZ10: Y
A11: 1033 | B11: Brijesh Kanchan | C11: M | D11: 101457287134 | E11: Union Bank of India | F11: 520291002188411 | G11: UBIN0901768 | I11: 30 | J11: 0 | K11: 0 | L11: 0 | M11: 30 | N11: 30 | O11: 0 | P11: -30 | Q11: 15000 | R11: 3540 | S11: 1180 | T11: 1180 | U11: 550 | V11: 550 | W11: 22000 | X11: #DIV/0! | Y11: #DIV/0! | Z11: #DIV/0! | AA11: #DIV/0! | AF11: 0 | AG11: #DIV/0! | AH11: #DIV/0! | AI11: #DIV/0! | AK11: #DIV/0! | AL11: #DIV/0! | AM11: #DIV/0! | AN11: #DIV/0! | AO11: #DIV/0! | AP11: #DIV/0! | AQ11: #DIV/0! | AR11: #DIV/0! | AS11: 0 | AT11: 0 | AV11: 0 | AY11: 0 | AZ11: Y
A12: 1034 | B12: Karthik | C12: M | D12: 101898645952 | E12: State Bank of India | F12: 20326554019 | G12: SBIN0017762 | J12: 0 | K12: 0 | L12: 0 | M12: 0 | N12: 0 | O12: 0 | P12: 0 | Q12: 15000 | R12: 4956 | S12: 1652 | T12: 1770 | U12: 3690 | V12: 3690 | W12: 30758 | X12: #DIV/0! | Y12: #DIV/0! | Z12: #DIV/0! | AA12: #DIV/0! | AB12: 0 | AC12: 0 | AD12: 0 | AE12: 0 | AF12: 0 | AG12: 0 | AH12: 0 | AI12: 0 | AK12: #DIV/0! | AL12: 0 | AM12: #DIV/0! | AN12: #DIV/0! | AO12: 0 | AP12: 0 | AQ12: #DIV/0! | AR12: #DIV/0! | AS12: 0 | AT12: 0 | AV12: 0 | AY12: 0 | AZ12: N
A13: 1036 | B13: Kiruthika Bala | C13: F | D13: 101867312879 | E13: State Bank of India | F13: 20082899400 | G13: SBIN0003143 | I13: 30 | J13: 30 | K13: 0 | L13: 3 | M13: 2.5 | N13: 0 | O13: 0.5 | P13: 30 | Q13: 15000 | R13: 4956 | S13: 1652 | T13: 1180 | U13: 3520 | V13: 3520 | W13: 29828 | X13: 15000 | Y13: 4956 | Z13: 1652 | AA13: 1180 | AB13: 3168 | AC13: 2816 | AF13: 0 | AG13: 1800 | AH13: 300 | AI13: 0 | AK13: 28772 | AL13: 2100 | AM13: 26672 | AN13: 26672 | AO13: 0 | AP13: 1800 | AQ13: 721.5 | AR13: 31293.5 | AS13: 0 | AT13: 0 | AV13: 0 | AY13: 0 | AZ13: Y
A14: 1037 | B14: Shrilatha Hegde | C14: F | D14: 100004572892 | E14: HDFC Bank | F14: 50100273530923 | G14: HDFC0001269 | I14: 30 | J14: 0 | K14: 0 | L14: 0 | M14: 0 | N14: 0 | O14: 0 | P14: 0 | Q14: 26000 | R14: 14808 | S14: 11106 | T14: 11106 | U14: 5395 | V14: 5395 | W14: 73810 | X14: #DIV/0! | Y14: #DIV/0! | Z14: #DIV/0! | AA14: #DIV/0! | AB14: 0 | AC14: 0 | AF14: 0 | AG14: #DIV/0! | AH14: #DIV/0! | AI14: 0 | AK14: #DIV/0! | AL14: #DIV/0! | AM14: #DIV/0! | AN14: #DIV/0! | AO14: 0 | AP14: #DIV/0! | AQ14: #DIV/0! | AR14: #DIV/0! | AS14: 0 | AT14: 0 | AV14: 0 | AY14: 0 | AZ14: N
A15: 1042 | B15: Vijay Corda | C15: M | D15: 101404270886 | E15: ICICI Bank | F15: 235101504681 | G15: ICIC0002351 | I15: 30 | J15: 30 | K15: 6 | L15: 3 | M15: 0 | N15: 0 | O15: 9 | P15: 30 | Q15: 30000 | R15: 21300 | S15: 15975 | T15: 12780 | U15: 7920 | V15: 7920 | W15: 95895 | X15: 30000 | Y15: 21300 | Z15: 15975 | AA15: 12780 | AB15: 7920 | AC15: 6336 | AF15: 0 | AG15: 1800 | AH15: 300 | AI15: 0 | AK15: 94311 | AL15: 2100 | AM15: 92211 | AN15: 92211 | AO15: 0 | AP15: 1800 | AQ15: 1443 | AR15: 97554 | AS15: 0 | AT15: 0 | AV15: 0 | AY15: 0 | AZ15: Y
A16: 1044 | B16: Amritha Vikram Shenoy | C16: F | D16: 101898706557 | E16: Canara Bank | F16: 2753101008732 | G16: CNRB0000611 | I16: 30 | J16: 30 | K16: 0 | L16: 0 | M16: 9 | N16: 9 | O16: 0 | P16: 21 | Q16: 26000 | R16: 11600 | S16: 10440 | T16: 8700 | U16: 0 | V16: 28875 | W16: 85615 | X16: 18200 | Y16: 8120 | Z16: 7308 | AA16: 6090 | AB16: 0 | AC16: 23100 | AF16: 0 | AG16: 1800 | AH16: 200 | AI16: 0 | AK16: 62818 | AL16: 2000 | AM16: 60818 | AN16: 60818 | AO16: 0 | AP16: 1800 | AQ16: 875.42 | AR16: 65493.42 | AS16: 0 | AT16: 0 | AV16: 0 | AY16: 0 | AZ16: Y
A17: 1047 | B17: Thulasi Ninnikal | C17: F | D17: 100393676148 | E17: Axis Bank | F17: 919010001528637 | G17: UTIB0000073 | I17: 30 | J17: 30 | K17: 0 | L17: 30 | M17: 30 | N17: 0 | O17: 0 | P17: 30 | Q17: 26000 | R17: 18750 | S17: 1250 | T17: 10833.333 | U17: 13125 | V17: 13125 | W17: 83083.333 | X17: 26000 | Y17: 18750 | Z17: 1250 | AA17: 10833.333 | AB17: 0 | AC17: 0 | AF17: 0 | AG17: 1800 | AH17: 300 | AI17: 0 | AK17: 56833.333 | AL17: 2100 | AM17: 54733.333 | AN17: 54733 | AO17: 0 | AP17: 1800 | AQ17: 1250.6 | AR17: 59883.933 | AS17: 0 | AT17: 0 | AV17: 0 | AY17: 0 | AZ17: Y
A18: 1039 | B18: Charith Raj | C18: M | D18: 101929473959 | E18: Karnataka Bank | F18: 6992500100773101 | G18: KARB0000699 | I18: 30 | J18: 30 | K18: 0.5 | L18: 3 | M18: 0.5 | N18: 0 | O18: 3 | P18: 30 | Q18: 15000 | R18: 5700 | S18: 1900 | T18: 1900 | U18: 2030 | V18: 2030 | W18: 28560 | X18: 15000 | Y18: 5700 | Z18: 1900 | AA18: 1900 | AB18: 1827 | AC18: 1624 | AF18: 0 | AG18: 1800 | AH18: 300 | AI18: 0 | AK18: 27951 | AL18: 2100 | AM18: 25851 | AN18: 25851 | AO18: 0 | AP18: 1800 | AQ18: 721.5 | AR18: 30472.5 | AS18: 0 | AT18: 0 | AV18: 0 | AY18: 0 | AZ18: Y
A19: 1040 | B19: Dheeraj | C19: M | D19: 101929655674 | E19: Karnataka Bank | F19: 4322500100894301 | G19: KARB0000432 | I19: 30 | J19: 30 | K19: 0.5 | L19: 3 | M19: 1 | N19: 0 | O19: 2.5 | P19: 30 | Q19: 15000 | R19: 5700 | S19: 1900 | T19: 1900 | U19: 2390 | V19: 2390 | W19: 29280 | X19: 15000 | Y19: 5700 | Z19: 1900 | AA19: 1900 | AB19: 2390 | AC19: 1912 | AF19: 0 | AG19: 1800 | AH19: 300 | AI19: 0 | AK19: 28802 | AL19: 2100 | AM19: 26702 | AN19: 26702 | AO19: 0 | AP19: 1800 | AQ19: 721.5 | AR19: 31323.5 | AS19: 0 | AT19: 0 | AV19: 0 | AY19: 0 | AZ19: Y
A20: 1043 | B20: Nithesha | C20: M | D20: 101938689117 | E20: Kotak Mahindra Bank | F20: 4447270132 | G20: KKBK0007937 | I20: 30 | J20: 30 | K20: 0 | L20: 3 | M20: 3 | N20: 0 | O20: 0 | P20: 30 | Q20: 15000 | R20: 5130 | S20: 1710 | T20: 1710 | U20: 1827 | V20: 1827 | W20: 27204 | X20: 15000 | Y20: 5130 | Z20: 1710 | AA20: 1710 | AB20: 1461.6 | AC20: 1461.6 | AF20: 0 | AG20: 1800 | AH20: 300 | AI20: 0 | AK20: 26473.2 | AL20: 2100 | AM20: 24373.2 | AN20: 24373 | AO20: 0 | AP20: 1800 | AQ20: 721.5 | AR20: 28994.7 | AS20: 0 | AT20: 0 | AV20: 0 | AY20: 0 | AZ20: Y
A21: 1045 | B21: Viola DSouza | C21: F | D21: 101938591137 | E21: Union Bank of India | F21: 520101012785829 | G21: UBIN0910848 | I21: 30 | J21: 0 | K21: 0 | L21: 0 | M21: 0 | N21: 0 | O21: 0 | P21: 0 | Q21: 0 | R21: 0 | S21: 0 | T21: 0 | U21: 0 | V21: 0 | W21: 0 | X21: 0 | Y21: 0 | Z21: 0 | AA21: 0 | AB21: 0 | AC21: 0 | AD21: 0 | AE21: 0 | AF21: 0 | AG21: 0 | AH21: 0 | AI21: 0 | AJ21: 0 | AK21: 0 | AL21: 0 | AM21: 0 | AN21: 0 | AO21: 0 | AP21: 0 | AQ21: 0 | AR21: 0 | AS21: 0 | AT21: 0 | AU21: 0 | AV21: 0 | AW21: 0 | AX21: 0 | AY21: 0 | AZ21: N
A22: 1046 | B22: Adithya Kini | C22: M | D22: 101959071464 | E22: Kotak Mahindra Bank | F22: 3948638991 | G22: KKBK0007937 | I22: 30 | J22: 30 | K22: 2.5 | L22: 5 | M22: 3.5 | N22: 0 | O22: 4 | P22: 30 | Q22: 15000 | R22: 5700 | S22: 1900 | T22: 1900 | U22: 2152 | V22: 2152 | W22: 28804 | X22: 15000 | Y22: 5700 | Z22: 1900 | AA22: 1900 | AB22: 1936.8 | AC22: 1721.6 | AF22: 0 | AG22: 1800 | AH22: 300 | AI22: 0 | AK22: 28158.4 | AL22: 2100 | AM22: 26058.4 | AN22: 26058 | AO22: 0 | AP22: 1800 | AQ22: 721.5 | AR22: 30679.9 | AS22: 0 | AT22: 0 | AV22: 0 | AY22: 0 | AZ22: Y
A23: 1048 | B23: Dashwitha Monteiro | C23: F | D23: 101974844713 | E23: Karnataka Bank | F23: 7532500102901901 | G23: KARB0000753 | I23: 30 | J23: 30 | K23: 0 | L23: 5.5 | M23: 3 | N23: 0 | O23: 2.5 | P23: 30 | Q23: 15000 | R23: 4959 | S23: 1653 | T23: 1653 | U23: 1283 | V23: 1283 | W23: 25831 | X23: 15000 | Y23: 4959 | Z23: 1653 | AA23: 1653 | AB23: 1154.7 | AC23: 1026.4 | AF23: 0 | AG23: 1800 | AH23: 100 | AI23: 0 | AK23: 25446.1 | AL23: 1900 | AM23: 23546.1 | AN23: 23546 | AO23: 0 | AP23: 1800 | AQ23: 721.5 | AR23: 27967.6 | AS23: 0 | AT23: 0 | AV23: 0 | AY23: 0 | AZ23: Y
A24: 1049 | B24: Karthik Shetty | C24: M | D24: 101974844732 | E24: Kotak Mahindra Bank | F24: 4447270118 | G24: KKBK0007937 | I24: 30 | J24: 30 | K24: 2 | L24: 3 | M24: 4.5 | N24: 0 | O24: 0.5 | P24: 30 | Q24: 15000 | R24: 6000 | S24: 5000 | T24: 6000 | U24: 4000 | V24: 4000 | W24: 40000 | X24: 15000 | Y24: 6000 | Z24: 5000 | AA24: 6000 | AB24: 4800 | AC24: 3200 | AF24: 0 | AG24: 1800 | AH24: 300 | AI24: 0 | AK24: 40000 | AL24: 2100 | AM24: 37900 | AN24: 37900 | AO24: 0 | AP24: 1800 | AQ24: 721.5 | AR24: 42521.5 | AS24: 0 | AT24: 0 | AV24: 0 | AY24: 0 | AZ24: Y
A25: 1050 | B25: Ananya MK | C25: F | D25: 101974844721 | E25: Union Bank | F25: 520101253032790 | G25: UBIN0901679 | I25: 30 | J25: 30 | K25: 0 | L25: 6 | M25: 3 | N25: 0 | O25: 3 | P25: 30 | Q25: 15000 | R25: 5700 | S25: 1900 | T25: 1900 | U25: 2833 | V25: 2833 | W25: 30166 | X25: 15000 | Y25: 5700 | Z25: 1900 | AA25: 1900 | AB25: 2833 | AC25: 2266.4 | AF25: 0 | AG25: 1800 | AH25: 300 | AI25: 0 | AK25: 29599.4 | AL25: 2100 | AM25: 27499.4 | AN25: 27499 | AO25: 0 | AP25: 1800 | AQ25: 721.5 | AR25: 32120.9 | AS25: 0 | AT25: 0 | AV25: 0 | AY25: 0 | AZ25: Y
A26: 1051 | B26: Suchithra Nayak | C26: F | D26: 102027953789 | E26: Bank of Baroda | F26: 81910100000314 | G26: BARB0VJKUKU | I26: 30 | J26: 30 | K26: 2 | L26: 5 | M26: 1 | N26: 0 | O26: 6 | P26: 30 | Q26: 15000 | R26: 3825 | S26: 1020 | T26: 1020 | U26: 2500 | V26: 2500 | W26: 25865 | X26: 15000 | Y26: 3825 | Z26: 1020 | AA26: 1020 | AF26: 0 | AG26: 1800 | AH26: 0 | AI26: 156.4875 | AK26: 20865 | AL26: 1956.4875 | AM26: 18908.513 | AN26: 18909 | AO26: 678.1125 | AP26: 1800 | AQ26: 721.5 | AR26: 24064.612 | AS26: 0 | AT26: 0 | AV26: 0 | AY26: 0 | AZ26: Y
A27: 1053 | B27: Nireeksha | C27: F | D27: 102027953770 | E27: Canara Bank | F27: 01792210015172 | G27: CNRB0010179 | I27: 30 | J27: 30 | K27: 0 | L27: 5 | M27: 2 | N27: 0 | O27: 3 | P27: 30 | Q27: 15000 | R27: 4845 | S27: 1615 | T27: 1615 | U27: 1378 | V27: 1378 | W27: 25831 | X27: 15000 | Y27: 4845 | Z27: 1615 | AA27: 1615 | AB27: 1102.4 | AC27: 1102.4 | AF27: 0 | AG27: 1800 | AH27: 300 | AI27: 0 | AK27: 25279.8 | AL27: 2100 | AM27: 23179.8 | AN27: 23180 | AO27: 0 | AP27: 1800 | AQ27: 721.5 | AR27: 27801.3 | AS27: 350000 | AT27: 350000 | AV27: 0 | AY27: 0 | AZ27: Y
A28: 1054 | B28: Srijan Mahale | C28: M | D28: 102004602624 | E28: Karnataka Bank | F28: 7552500101343501 | G28: KARB0000755 | I28: 30 | J28: 30 | K28: 4.5 | L28: 3 | M28: 3 | N28: 0 | O28: 4.5 | P28: 30 | Q28: 15000 | R28: 4000 | S28: 4000 | T28: 4000 | U28: 3000 | V28: 3000 | W28: 33000 | X28: 15000 | Y28: 4000 | Z28: 4000 | AA28: 4000 | AB28: 3600 | AC28: 2400 | AF28: 0 | AG28: 1800 | AH28: 300 | AI28: 0 | AK28: 33000 | AL28: 2100 | AM28: 30900 | AN28: 30900 | AO28: 0 | AP28: 1800 | AQ28: 721.5 | AR28: 35521.5 | AS28: 0 | AT28: 0 | AV28: 0 | AY28: 0 | AZ28: Y
A29: 1055 | B29: Aniruddha Kulkarni | C29: M | D29: 102038520969 | E29: Canara Bank | F29: 3448101004542 | G29: CNRB0003448 | I29: 30 | J29: 30 | K29: 4.5 | L29: 3.5 | M29: 0.5 | N29: 0 | O29: 7.5 | P29: 30 | Q29: 15000 | R29: 3000 | S29: 1800 | T29: 1800 | U29: 1900 | V29: 1900 | W29: 25400 | X29: 15000 | Y29: 3000 | Z29: 1800 | AA29: 1800 | AB29: 2090 | AC29: 1520 | AF29: 0 | AG29: 1800 | AH29: 300 | AI29: 0 | AK29: 25210 | AL29: 2100 | AM29: 23110 | AN29: 23110 | AO29: 0 | AP29: 1800 | AQ29: 721.5 | AR29: 27731.5 | AS29: 0 | AT29: 0 | AV29: 0 | AY29: 0 | AZ29: Y
A30: 1057 | B30: Ashish V Kumar | C30: M | D30: 101744660729 | E30: Union Bank | F30: 520101001707538 | G30: UBIN0930881 | I30: 30 | J30: 30 | K30: 1 | L30: 3.5 | M30: 0 | N30: 0 | O30: 4.5 | P30: 30 | Q30: 15000 | R30: 2800 | S30: 1800 | T30: 1300 | U30: 1600 | V30: 1600 | W30: 24100 | X30: 15000 | Y30: 2800 | Z30: 1800 | AA30: 1300 | AF30: 0 | AG30: 1800 | AH30: 0 | AI30: 156.75 | AK30: 20900 | AL30: 1956.75 | AM30: 18943.25 | AN30: 18943 | AO30: 679.25 | AP30: 1800 | AQ30: 721.5 | AR30: 24100.75 | AS30: 250000 | AT30: 220000 | AV30: 0 | AY30: 30000 | AZ30: Y
A31: 1058 | B31: Shwan Prajwal DSouza | C31: M | D31: 101729961853 | E31: Canara Bank | F31: 3448101002990 | G31: CNRB0003448 | I31: 30 | J31: 30 | K31: 1 | L31: 4.5 | M31: 3 | N31: 0 | O31: 2.5 | P31: 30 | Q31: 15000 | R31: 2800 | S31: 1800 | T31: 1300 | U31: 1600 | V31: 1600 | W31: 24100 | X31: 15000 | Y31: 2800 | Z31: 1800 | AA31: 1300 | AF31: 0 | AG31: 1800 | AH31: 0 | AI31: 156.75 | AK31: 20900 | AL31: 1956.75 | AM31: 18943.25 | AN31: 18943 | AO31: 679.25 | AP31: 1800 | AQ31: 721.5 | AR31: 24100.75 | AS31: 0 | AT31: 0 | AV31: 0 | AY31: 0 | AZ31: Y
A32: 1059 | B32: Rajesh A A Gowda | C32: M | E32: Axis Bank | F32: 404010100044970 | G32: UTIB0003855 | I32: 30 | J32: 30 | K32: 1 | L32: 4 | M32: 2 | N32: 0 | O32: 3 | P32: 30 | Q32: 90000 | W32: 90000 | X32: 90000 | Y32: 0 | Z32: 0 | AA32: 0 | AB32: 0 | AC32: 0 | AF32: 0 | AG32: 0 | AH32: 0 | AI32: 0 | AK32: 90000 | AL32: 9000 | AM32: 90000 | AN32: 81000 | AO32: 0 | AP32: 0 | AQ32: 4329 | AR32: 94329 | AS32: 0 | AT32: 0 | AU32: 9000 | AV32: 0 | AW32: 9000 | AY32: 0 | AZ32: Y
A33: 1062 | B33: Shashank Rai | C33: M | E33: Bank of Baroda | F33: 70670100003120 | G33: BARB0VJSHIS | I33: 30 | J33: 30 | K33: 0 | L33: 3 | M33: 4 | N33: 1 | O33: 0 | P33: 29 | Q33: 15000 | R33: 1500 | U33: 1000 | V33: 1000 | W33: 18500 | X33: 14500 | Y33: 1450 | Z33: 0 | AA33: 0 | AB33: 800 | AC33: 800 | AF33: 0 | AG33: 1740 | AH33: 0 | AI33: 119.625 | AJ33: 1500 | AK33: 17550 | AL33: 3359.625 | AM33: 14190.375 | AN33: 14190 | AO33: 518.375 | AP33: 1740 | AQ33: 697.45 | AR33: 20505.825 | AS33: 45500 | AT33: 44000 | AV33: 0 | AY33: 0 | AZ33: Y
A34: 1063 | B34: Ashwith Poojary | C34: M | E34: Union Bank of India | F34: 520101257301698 | G34: UBIN0552011 | I34: 30 | J34: 30 | K34: 2 | L34: 4 | M34: 1 | N34: 0 | O34: 5 | P34: 30 | Q34: 15000 | R34: 3500 | U34: 1000 | V34: 1000 | W34: 20500 | X34: 15000 | Y34: 3500 | Z34: 0 | AA34: 0 | AB34: 800 | AC34: 800 | AF34: 0 | AG34: 1800 | AH34: 0 | AI34: 138.75 | AK34: 20100 | AL34: 1938.75 | AM34: 18161.25 | AN34: 18161 | AO34: 601.25 | AP34: 1800 | AQ34: 721.5 | AR34: 23222.75 | AS34: 0 | AT34: 0 | AV34: 0 | AY34: 0 | AZ34: Y
A35: 1064 | B35: Keerthan N | C35: M | E35: CANARA BANK | F35: 110138028402 | G35: CNRB0000657 | I35: 30 | J35: 30 | K35: 0 | L35: 3 | M35: 0.5 | N35: 0 | O35: 2.5 | P35: 30 | Q35: 15000 | R35: 1000 | S35: 1000 | U35: 250 | V35: 250 | W35: 17500 | X35: 15000 | Y35: 1000 | Z35: 1000 | AA35: 0 | AB35: 200 | AC35: 200 | AF35: 0 | AG35: 1800 | AH35: 0 | AI35: 127.5 | AK35: 17400 | AL35: 1927.5 | AM35: 15472.5 | AN35: 15473 | AO35: 552.5 | AP35: 1800 | AQ35: 721.5 | AR35: 20474 | AZ35: Y
A36: 1065 | B36: Likhitha | C36: F | I36: 30 | J36: 0 | K36: 0 | L36: 0 | M36: 0 | N36: 0 | O36: 0 | P36: 0 | Q36: 0 | R36: 0 | S36: 0 | T36: 0 | U36: 0 | V36: 0 | W36: 0 | X36: 0 | Y36: 0 | Z36: 0 | AA36: 0 | AB36: 0 | AC36: 0 | AD36: 0 | AE36: 0 | AF36: 0 | AG36: 0 | AH36: 0 | AI36: 0 | AJ36: 0 | AK36: 0 | AL36: 0 | AM36: 0 | AN36: 0 | AO36: 0 | AP36: 0 | AQ36: 0 | AR36: 0 | AS36: 0 | AT36: 0 | AU36: 0 | AV36: 0 | AW36: 0 | AX36: 0 | AY36: 0 | AZ36: N
A37: 1066 | B37: Hrishikesh Shetty | C37: M | E37: bank of baroda | F37: 71360100016687 | G37: BARB0VJKMBA | I37: 30 | J37: 30 | K37: 1 | L37: 3 | M37: 2 | N37: 0 | O37: 2 | P37: 30 | Q37: 10000 | R37: 0 | S37: 0 | T37: 0 | U37: 0 | V37: 0 | W37: 10000 | X37: 10000 | Y37: 0 | Z37: 0 | AA37: 0 | AB37: 0 | AC37: 0 | AD37: 0 | AE37: 0 | AF37: 0 | AG37: 0 | AH37: 0 | AI37: 0 | AJ37: 0 | AK37: 10000 | AL37: 0 | AM37: 10000 | AN37: 10000 | AO37: 0 | AP37: 0 | AQ37: 0 | AR37: 0 | AS37: 0 | AT37: 0 | AU37: 0 | AV37: 0 | AW37: 0 | AX37: 0 | AY37: 0 | AZ37: Y
A38: 1067 | B38: Abdul Hadi Bin Nizar | C38: M | E38: HDFC Bank | F38: 50100124674434 | G38: HDFC0000361 | I38: 30 | J38: 30 | K38: 0 | L38: 3 | M38: 2 | N38: 0 | O38: 1 | P38: 30 | Q38: 75000 | W38: 75000 | X38: 75000 | Y38: 0 | Z38: 0 | AA38: 0 | AB38: 0 | AC38: 0 | AF38: 0 | AG38: 0 | AH38: 0 | AI38: 0 | AK38: 75000 | AL38: 7500 | AM38: 75000 | AN38: 67500 | AO38: 0 | AP38: 0 | AR38: 75000 | AS38: 0 | AT38: 0 | AU38: 7500 | AV38: 0 | AW38: 7500 | AY38: 0 | AZ38: Y
A39: 1068 | B39: Sharon Brayan DSouza | C39: M | I39: 30 | J39: 25 | L39: 3 | M39: 1 | N39: 0 | O39: 2 | P39: 25 | Q39: 12000 | W39: 12000 | X39: 10000 | AK39: 10000 | AL39: 0 | AM39: 10000 | AN39: 10000 | AO39: 0 | AQ39: 0 | AR39: 10000 | AV39: 0 | AW39: 0 | AY39: 0 | AZ39: Y
A40: 1069 | B40: Manoj Shetty | C40: M | I40: 30 | J40: 18 | L40: 3 | M40: 0 | N40: 0 | O40: 3 | P40: 18 | Q40: 12000 | W40: 12000 | X40: 7200 | AK40: 7200 | AL40: 0 | AM40: 7200 | AN40: 7200 | AO40: 0 | AQ40: 0 | AR40: 7200 | AZ40: Y
...

Sheet Apr 2025
B1: 45748 | X1: Earnings | AG1: Deductions
A2: Employee ID | B2: Employee Name | C2: Gender | D2: UAN | E2: Bank Name | F2: Bank Account # | G2: Bank IFSC Code | H2: City | I2: Days in month | J2: Days of Pay | K2: Opening Leave Balance | L2: Eligible Leaves | M2: Leaves Availed | N2: Loss of Pay Days | O2: Closing Leave Balance | P2: Payable Days | Q2: Basic + DA | R2: HRA | S2: Medical allowance | T2: Conveyance | U2: Individual Performance Incentive | V2: Company Performance Incentive | W2: Total Fixed Salary | X2: Payable Basic + DA | Y2: Payable HRA | Z2: Payable Medical Allowance | AA2: Payable Conveyance | AB2: Individual Performance Incentive | AC2: Company Performance Incentive | AD2: Salary Loan availed this month | AE2: Other Arrears / Incentives | AF2: Bonus Accrued | AG2: Provident Fund (PF) | AH2: Professional Tax (PT) | AI2: Employees' State Insurance (ESI) | AJ2: Loan EMI | AK2: Total Additions | AL2: Total Deductions | AM2: Total Salary | AN2: Payable Salary | AO2: Employer contribution to ESI | AP2: Employer contribution to PF | AQ2: Gratuity | AR2: Total CTC | AS2: Previous Loan Balance | AT2: Closing Loan Balance | AU2: Tax Deduction on Source (TDS) | AV2: Annual Bonus | AW2: Cumulative TDS for this FY | AX2: Remarks | AY2: Loan repayment outside Salary | AZ2: Active (Y/N)
A3: 1 | B3: Saumya R Rao | C3: F | D3: 101898706542 | E3: HDFC Bank | F3: 12691870000226 | G3: HDFC0001269 | I3: 30 | J3: 30 | K3: 8 | L3: 3 | M3: 0 | N3: 0 | O3: 11 | P3: 30 | Q3: 30000 | R3: 12500 | S3: 5000 | T3: 7500 | U3: 0 | V3: 40000 | W3: 95000 | X3: 30000 | Y3: 12500 | Z3: 5000 | AA3: 7500 | AC3: 28000 | AF3: 0 | AG3: 1800 | AH3: 200 | AI3: 0 | AK3: 83000 | AL3: 2000 | AM3: 81000 | AN3: 81000 | AO3: 0 | AP3: 1800 | AR3: 84800 | AS3: 0 | AT3: 0 | AV3: 0 | AY3: 0 | AZ3: Y
A4: 2 | B4: Kiran Sham Khandige | C4: M | D4: 100193986476 | E4: ICICI bank | F4: 1401514208 | G4: ICIC0000014 | I4: 30 | J4: 30 | K4: 8 | L4: 3 | M4: 0 | N4: 0 | O4: 11 | P4: 30 | Q4: 30000 | R4: 12500 | S4: 5000 | T4: 7500 | U4: 0 | V4: 40000 | W4: 95000 | X4: 30000 | Y4: 12500 | Z4: 5000 | AA4: 7500 | AC4: 28000 | AF4: 0 | AG4: 1800 | AH4: 200 | AI4: 0 | AK4: 83000 | AL4: 2000 | AM4: 81000 | AN4: 81000 | AO4: 0 | AP4: 1800 | AR4: 84800 | AS4: 0 | AT4: 0 | AV4: 0 | AY4: 0 | AZ4: Y
A5: 1001 | B5: Dinesh | C5: M | D5: 101404270926 | E5: Kotak Mahindra Bank | F5: 1113584104 | G5: KKBK0007937 | I5: 30 | J5: 30 | K5: 0 | L5: 3 | M5: 0.5 | N5: 0 | O5: 2.5 | P5: 30 | Q5: 15000 | R5: 3540 | S5: 1180 | T5: 1180 | U5: 2123 | V5: 2123 | W5: 25146 | X5: 15000 | Y5: 3540 | Z5: 1180 | AA5: 1180 | AD5: 0 | AF5: 2138 | AG5: 1800 | AH5: 0 | AI5: 157 | AJ5: 25000 | AK5: 23038 | AL5: 26957 | AM5: -3919 | AN5: 19599 | AO5: 679 | AP5: 1950 | AR5: 25667 | AS5: 185000 | AT5: 160000 | AV5: 25656 | AY5: 0 | AZ5: Y
A6: 1006 | B6: Rakshita Salyan | C6: F | D6: 101404270893 | E6: Kotak Mahindra Bank | F6: 1113586177 | G6: KKBK0007937 | I6: 30 | J6: 30 | K6: 2 | L6: 3 | M6: 0.5 | N6: 0 | O6: 4.5 | P6: 30 | Q6: 15000 | R6: 3540 | S6: 1180 | T6: 1180 | U6: 2668 | V6: 2668 | W6: 26236 | X6: 15000 | Y6: 3540 | Z6: 1180 | AA6: 1180 | AD6: 0 | AF6: 2220 | AG6: 1800 | AH6: 0 | AI6: 157 | AJ6: 5000 | AK6: 23120 | AL6: 6957 | AM6: 16163 | AN6: 40583 | AO6: 679 | AP6: 1950 | AR6: 25749 | AS6: 190000 | AT6: 185000 | AV6: 26640 | AY6: 0 | AZ6: Y
A7: 1024 | B7: Dishanth D | C7: M | D7: 101818017017 | E7: Kotak Mahindra Bank | F7: 3948638977 | G7: KKBK0007937 | I7: 30 | J7: 30 | K7: 4 | L7: 3 | M7: 3 | N7: 0 | O7: 4 | P7: 30 | Q7: 15000 | R7: 2388 | S7: 796 | T7: 796 | U7: 500 | V7: 500 | W7: 19980 | X7: 15000 | Y7: 2388 | Z7: 796 | AA7: 796 | AF7: 1690 | AG7: 1800 | AH7: 0 | AI7: 142 | AJ7: 2000 | AK7: 20670 | AL7: 3942 | AM7: 16728 | AN7: 35318 | AO7: 617 | AP7: 1800 | AR7: 23087 | AS7: 21500 | AT7: 19500 | AV7: 20280 | AY7: 0 | AZ7: Y
A8: 1028 | B8: Veeralakshmi R | C8: F | D8: 101768643043 | E8: HDFC Bank | F8: 50100454812858 | G8: HDFC0003699 | I8: 30 | J8: 30 | K8: 0 | L8: 3 | M8: 1 | N8: 0 | O8: 2 | P8: 30 | Q8: 15000 | R8: 7000 | S8: 6000 | T8: 5000 | U8: 5000 | V8: 5000 | W8: 43000 | X8: 15000 | Y8: 7000 | Z8: 6000 | AA8: 5000 | AB8: 5000 | AC8: 3500 | AF8: 0 | AG8: 1800 | AH8: 200 | AI8: 0 | AK8: 41500 | AL8: 2000 | AM8: 39500 | AN8: 39500 | AO8: 0 | AP8: 1800 | AR8: 43300 | AS8: 0 | AT8: 0 | AV8: 0 | AY8: 0 | AZ8: Y
A9: 1030 | B9: Sushmitha Shetty | C9: F | D9: 101657750048 | E9: Bank of Baroda | F9: 82010100004480 | G9: BARB0VJKARK | I9: 30 | J9: 30 | K9: 0 | L9: 3 | M9: 0 | N9: 0 | O9: 3 | P9: 30 | Q9: 15000 | R9: 3540 | S9: 1180 | T9: 1180 | U9: 2150 | V9: 2150 | W9: 25200 | X9: 15000 | Y9: 3540 | Z9: 1180 | AA9: 1180 | AF9: 0 | AG9: 1800 | AH9: 0 | AI9: 157 | AK9: 20900 | AL9: 1957 | AM9: 18943 | AN9: 18943 | AO9: 679 | AP9: 1800 | AR9: 23379 | AS9: 0 | AT9: 0 | AV9: 0 | AY9: 0 | AZ9: Y
A10: 1031 | B10: Gururaj Shet | C10: M | D10: 101767120465 | E10: Karnataka Bank | F10: 4782500102104101 | G10: KARB0000478 | I10: 30 | J10: 30 | K10: 0 | L10: 3 | M10: 1 | N10: 0 | O10: 2 | P10: 30 | Q10: 15000 | R10: 9000 | S10: 8000 | T10: 3000 | U10: 6000 | V10: 6000 | W10: 47000 | X10: 15000 | Y10: 9000 | Z10: 8000 | AA10: 3000 | AB10: 6600 | AC10: 4200 | AF10: 0 | AG10: 1800 | AH10: 200 | AI10: 0 | AK10: 45800 | AL10: 2000 | AM10: 43800 | AN10: 43800 | AO10: 0 | AP10: 1800 | AR10: 47600 | AS10: 0 | AT10: 0 | AV10: 0 | AY10: 0 | AZ10: Y
A11: 1033 | B11: Brijesh Kanchan | C11: M | D11: 101457287134 | E11: Union Bank of India | F11: 520291002188411 | G11: UBIN0901768 | I11: 30 | J11: 30 | K11: 0 | L11: 3 | M11: 2 | N11: 0 | O11: 1 | P11: 30 | Q11: 15000 | R11: 3540 | S11: 1180 | T11: 1180 | U11: 550 | V11: 550 | W11: 22000 | X11: 15000 | Y11: 3540 | Z11: 1180 | AA11: 1180 | AF11: 0 | AG11: 1800 | AH11: 0 | AI11: 157 | AK11: 20900 | AL11: 1957 | AM11: 18943 | AN11: 18943 | AO11: 679 | AP11: 1800 | AR11: 23379 | AS11: 0 | AT11: 0 | AV11: 0 | AY11: 0 | AZ11: Y
A12: 1034 | B12: Karthik | C12: M | D12: 101898645952 | E12: State Bank of India | F12: 20326554019 | G12: SBIN0017762 | I12: 30 | J12: 30 | K12: 0 | L12: 3 | M12: 3 | N12: 0 | O12: 0 | P12: 30 | Q12: 15000 | R12: 3540 | S12: 1180 | T12: 1180 | U12: 2050 | V12: 2050 | W12: 25000 | X12: 15000 | Y12: 3540 | Z12: 1180 | AA12: 1180 | AF12: 0 | AG12: 1800 | AH12: 0 | AI12: 157 | AK12: 20900 | AL12: 1957 | AM12: 18943 | AN12: 18943 | AO12: 679 | AP12: 1800 | AR12: 23379 | AS12: 0 | AT12: 0 | AV12: 0 | AY12: 0 | AZ12: Y
A13: 1036 | B13: Kiruthika Bala | C13: F | D13: 101867312879 | E13: State Bank of India | F13: 20082899400 | G13: SBIN0003143 | I13: 30 | J13: 30 | K13: 0 | L13: 3 | M13: 3 | N13: 0 | O13: 0 | P13: 30 | Q13: 15000 | R13: 3540 | S13: 1180 | T13: 1180 | U13: 2200 | V13: 2200 | W13: 25300 | X13: 15000 | Y13: 3540 | Z13: 1180 | AA13: 1180 | AF13: 0 | AG13: 1800 | AH13: 0 | AI13: 157 | AK13: 20900 | AL13: 1957 | AM13: 18943 | AN13: 18943 | AO13: 679 | AP13: 1800 | AR13: 23379 | AS13: 0 | AT13: 0 | AV13: 0 | AY13: 0 | AZ13: Y
A14: 1037 | B14: Shrilatha Hegde | C14: F | D14: 100004572892 | E14: HDFC Bank | F14: 50100273530923 | G14: HDFC0001269 | I14: 30 | J14: 30 | K14: 0 | L14: 3 | M14: 0.5 | N14: 0 | O14: 2.5 | P14: 30 | Q14: 26000 | R14: 14808 | S14: 11106 | T14: 11106 | U14: 5395 | V14: 5395 | W14: 73810 | X14: 26000 | Y14: 14808 | Z14: 11106 | AA14: 11106 | AB14: 4316 | AC14: 3777 | AF14: 0 | AG14: 1800 | AH14: 200 | AI14: 0 | AK14: 71113 | AL14: 2000 | AM14: 69113 | AN14: 69113 | AO14: 0 | AP14: 1800 | AR14: 72913 | AS14: 0 | AT14: 0 | AV14: 0 | AY14: 0 | AZ14: Y
A15: 1042 | B15: Vijay Corda | C15: M | D15: 101404270886 | E15: ICICI Bank | F15: 235101504681 | G15: ICIC0002351 | I15: 30 | J15: 30 | K15: 3 | L15: 3 | M15: 0 | N15: 0 | O15: 6 | P15: 30 | Q15: 30000 | R15: 17040 | S15: 12780 | T15: 12780 | U15: 6600 | V15: 6600 | W15: 85800 | X15: 30000 | Y15: 17040 | Z15: 12780 | AA15: 12780 | AB15: 6600 | AC15: 4620 | AF15: 0 | AG15: 1800 | AH15: 200 | AI15: 0 | AK15: 83820 | AL15: 2000 | AM15: 81820 | AN15: 81820 | AO15: 0 | AP15: 1800 | AR15: 85620 | AS15: 0 | AT15: 0 | AV15: 0 | AY15: 0 | AZ15: Y
A16: 1044 | B16: Amritha Vikram Shenoy | C16: F | D16: 101898706557 | E16: Canara Bank | F16: 2753101008732 | G16: CNRB0000611 | I16: 30 | J16: 30 | K16: 0 | L16: 3 | M16: 8 | N16: 5 | O16: 0 | P16: 25 | Q16: 26000 | R16: 11600 | S16: 8700 | T16: 8700 | U16: 0 | V16: 27500 | W16: 82500 | X16: 21667 | Y16: 9667 | Z16: 7250 | AA16: 7250 | AB16: 0 | AC16: 19250 | AF16: 0 | AG16: 1800 | AH16: 200 | AI16: 0 | AK16: 65083 | AL16: 2000 | AM16: 63083 | AN16: 63083 | AO16: 0 | AP16: 1800 | AR16: 66883 | AS16: 0 | AT16: 0 | AV16: 0 | AY16: 0 | AZ16: Y
A17: 1047 | B17: Thulasi Ninnikal | C17: F | D17: 100393676148 | E17: Axis Bank | F17: 919010001528637 | G17: UTIB0000073 | I17: 30 | J17: 30 | K17: 6 | L17: 3 | M17: 1.5 | N17: 0 | O17: 7.5 | P17: 30 | Q17: 26000 | R17: 18750 | S17: 1250 | T17: 10833 | U17: 8125 | V17: 8125 | W17: 73083 | X17: 26000 | Y17: 18750 | Z17: 1250 | AA17: 10833 | AB17: 8125 | AC17: 5688 | AF17: 0 | AG17: 1800 | AH17: 200 | AI17: 0 | AK17: 70646 | AL17: 2000 | AM17: 68646 | AN17: 68646 | AO17: 0 | AP17: 1800 | AR17: 72446 | AS17: 0 | AT17: 0 | AV17: 0 | AY17: 0 | AZ17: Y
A18: 1039 | B18: Charith Raj | C18: M | D18: 101929473959 | E18: Karnataka Bank | F18: 6992500100773101 | G18: KARB0000699 | I18: 30 | J18: 30 | K18: 1 | L18: 3 | M18: 2 | N18: 0 | O18: 2 | P18: 30 | Q18: 15000 | R18: 2850 | S18: 950 | T18: 950 | U18: 1015 | V18: 1015 | W18: 21780 | X18: 15000 | Y18: 2850 | Z18: 950 | AA18: 950 | AF18: 0 | AG18: 1800 | AH18: 0 | AI18: 148 | AK18: 19750 | AL18: 1948 | AM18: 17802 | AN18: 17802 | AO18: 642 | AP18: 1800 | AR18: 22192 | AS18: 0 | AT18: 0 | AV18: 0 | AY18: 0 | AZ18: Y
A19: 1040 | B19: Dheeraj | C19: M | D19: 101929655674 | E19: Karnataka Bank | F19: 4322500100894301 | G19: KARB0000432 | I19: 30 | J19: 30 | K19: 0 | L19: 3 | M19: 0 | N19: 0 | O19: 3 | P19: 30 | Q19: 15000 | R19: 2850 | S19: 950 | T19: 950 | U19: 1195 | V19: 1195 | W19: 22140 | X19: 15000 | Y19: 2850 | Z19: 950 | AA19: 950 | AF19: 0 | AG19: 1800 | AH19: 0 | AI19: 148 | AK19: 19750 | AL19: 1948 | AM19: 17802 | AN19: 17802 | AO19: 642 | AP19: 1800 | AR19: 22192 | AS19: 0 | AT19: 0 | AV19: 0 | AY19: 0 | AZ19: Y
A20: 1043 | B20: Nithesha | C20: M | D20: 101938689117 | E20: Kotak Mahindra Bank | F20: 4447270132 | G20: KKBK0007937 | I20: 30 | J20: 30 | K20: 0 | L20: 3 | M20: 1.5 | N20: 0 | O20: 1.5 | P20: 30 | Q20: 15000 | R20: 2850 | S20: 950 | T20: 950 | U20: 1015 | V20: 1015 | W20: 21780 | X20: 15000 | Y20: 2850 | Z20: 950 | AA20: 950 | AF20: 0 | AG20: 1800 | AH20: 0 | AI20: 148 | AK20: 19750 | AL20: 1948 | AM20: 17802 | AN20: 17802 | AO20: 642 | AP20: 1800 | AR20: 22192 | AS20: 0 | AT20: 0 | AV20: 0 | AY20: 0 | AZ20: Y
A21: 1045 | B21: Viola DSouza | C21: F | D21: 101938591137 | E21: Union Bank of India | F21: 520101012785829 | G21: UBIN0910848 | I21: 30 | J21: 30 | K21: 0.5 | L21: 3 | M21: 0.5 | N21: 0 | O21: 3 | P21: 30 | Q21: 15000 | R21: 2850 | S21: 950 | T21: 950 | U21: 1195 | V21: 1195 | W21: 22140 | X21: 15000 | Y21: 2850 | Z21: 950 | AA21: 950 | AF21: 0 | AG21: 1800 | AH21: 0 | AI21: 148 | AK21: 19750 | AL21: 1948 | AM21: 17802 | AN21: 17802 | AO21: 642 | AP21: 1800 | AR21: 22192 | AS21: 0 | AT21: 0 | AV21: 0 | AY21: 0 | AZ21: Y
A22: 1046 | B22: Adithya Kini | C22: M | D22: 101959071464 | E22: Kotak Mahindra Bank | F22: 3948638991 | G22: KKBK0007937 | I22: 30 | J22: 30 | K22: 0.5 | L22: 3 | M22: 1.5 | N22: 0 | O22: 2 | P22: 30 | Q22: 15000 | R22: 2850 | S22: 950 | T22: 950 | U22: 1133 | V22: 1133 | W22: 22016 | X22: 15000 | Y22: 2850 | Z22: 950 | AA22: 950 | AF22: 0 | AG22: 1800 | AH22: 0 | AI22: 148 | AK22: 19750 | AL22: 1948 | AM22: 17802 | AN22: 17802 | AO22: 642 | AP22: 1800 | AR22: 22192 | AS22: 0 | AT22: 0 | AV22: 0 | AY22: 0 | AZ22: Y
A23: 1048 | B23: Dashwitha Monteiro | C23: F | D23: 101974844713 | E23: Karnataka Bank | F23: 7532500102901901 | G23: KARB0000753 | I23: 30 | J23: 30 | K23: 0.5 | L23: 3 | M23: 0.5 | N23: 0 | O23: 3 | P23: 30 | Q23: 15000 | R23: 2610 | S23: 870 | T23: 870 | U23: 675 | V23: 675 | W23: 20700 | X23: 15000 | Y23: 2610 | Z23: 870 | AA23: 870 | AF23: 0 | AG23: 1800 | AH23: 0 | AI23: 145 | AK23: 19350 | AL23: 1945 | AM23: 17405 | AN23: 17405 | AO23: 629 | AP23: 1800 | AR23: 21779 | AS23: 0 | AT23: 0 | AV23: 0 | AY23: 0 | AZ23: Y
A24: 1049 | B24: Karthik Shetty | C24: M | D24: 101974844732 | E24: Kotak Mahindra Bank | F24: 4447270118 | G24: KKBK0007937 | I24: 30 | J24: 30 | K24: 0 | L24: 3 | M24: 3 | N24: 0 | O24: 0 | P24: 30 | Q24: 15000 | R24: 5000 | S24: 4000 | T24: 5000 | U24: 3000 | V24: 3000 | W24: 35000 | X24: 15000 | Y24: 5000 | Z24: 4000 | AA24: 5000 | AB24: 3000 | AC24: 2100 | AF24: 0 | AG24: 1800 | AH24: 200 | AI24: 0 | AK24: 34100 | AL24: 2000 | AM24: 32100 | AN24: 32100 | AO24: 0 | AP24: 1800 | AR24: 35900 | AS24: 0 | AT24: 0 | AV24: 0 | AY24: 0 | AZ24: Y
A25: 1050 | B25: Ananya MK | C25: F | D25: 101974844721 | E25: Union Bank | F25: 520101253032790 | G25: UBIN0901679 | I25: 30 | J25: 30 | K25: 1.5 | L25: 3 | M25: 0 | N25: 0 | O25: 4.5 | P25: 30 | Q25: 15000 | R25: 2850 | S25: 950 | T25: 950 | U25: 1133 | V25: 1133 | W25: 22016 | X25: 15000 | Y25: 2850 | Z25: 950 | AA25: 950 | AF25: 0 | AG25: 1800 | AH25: 0 | AI25: 148 | AK25: 19750 | AL25: 1948 | AM25: 17802 | AN25: 17802 | AO25: 642 | AP25: 1800 | AR25: 22192 | AS25: 0 | AT25: 0 | AV25: 0 | AY25: 0 | AZ25: Y
A26: 1051 | B26: Suchithra Nayak | C26: F | D26: 102027953789 | E26: Bank of Baroda | F26: 81910100000314 | G26: BARB0VJKUKU | I26: 30 | J26: 30 | K26: 2 | L26: 3 | M26: 5 | N26: 0 | O26: 0 | P26: 30 | Q26: 15000 | R26: 2550 | S26: 850 | T26: 850 | U26: 725 | V26: 725 | W26: 20700 | X26: 15000 | Y26: 2550 | Z26: 850 | AA26: 850 | AF26: 0 | AG26: 1800 | AH26: 0 | AI26: 144 | AK26: 19250 | AL26: 1944 | AM26: 17306 | AN26: 17306 | AO26: 626 | AP26: 1800 | AR26: 21676 | AS26: 0 | AT26: 0 | AV26: 0 | AY26: 0 | AZ26: Y
A27: 1053 | B27: Nireeksha | C27: F | D27: 102027953770 | E27: Canara Bank | F27: 1792210015172 | G27: CNRB0010179 | I27: 30 | J27: 30 | K27: 0 | L27: 3 | M27: 1 | N27: 0 | O27: 2 | P27: 30 | Q27: 15000 | R27: 2550 | S27: 850 | T27: 850 | U27: 725 | V27: 725 | W27: 20700 | X27: 15000 | Y27: 2550 | Z27: 850 | AA27: 850 | AF27: 0 | AG27: 1800 | AH27: 0 | AI27: 144 | AK27: 19250 | AL27: 1944 | AM27: 17306 | AN27: 17306 | AO27: 626 | AP27: 1800 | AR27: 21676 | AS27: 0 | AT27: 0 | AV27: 0 | AY27: 0 | AZ27: Y
A28: 1054 | B28: Srijan Mahale | C28: M | D28: 102004602624 | E28: Karnataka Bank | F28: 7552500101343501 | G28: KARB0000755 | I28: 30 | J28: 30 | K28: 2.5 | L28: 3 | M28: 0 | N28: 0 | O28: 5.5 | P28: 30 | Q28: 15000 | R28: 4000 | S28: 4000 | T28: 4000 | U28: 3000 | V28: 3000 | W28: 33000 | X28: 15000 | Y28: 4000 | Z28: 4000 | AA28: 4000 | AB28: 3000 | AC28: 2100 | AF28: 0 | AG28: 1800 | AH28: 200 | AI28: 0 | AK28: 32100 | AL28: 2000 | AM28: 30100 | AN28: 30100 | AO28: 0 | AP28: 1800 | AR28: 33900 | AS28: 0 | AT28: 0 | AV28: 0 | AY28: 0 | AZ28: Y
A29: 1055 | B29: Aniruddha Kulkarni | C29: M | D29: 102038520969 | E29: Canara Bank | F29: 3448101004542 | G29: CNRB0003448 | I29: 30 | J29: 30 | K29: 3.5 | L29: 3 | M29: 1 | N29: 0 | O29: 5.5 | P29: 30 | Q29: 15000 | R29: 2000 | S29: 0 | T29: 0 | U29: 1000 | V29: 1000 | W29: 19000 | X29: 15000 | Y29: 2000 | Z29: 0 | AA29: 0 | AF29: 0 | AG29: 1800 | AH29: 0 | AI29: 128 | AK29: 17000 | AL29: 1928 | AM29: 15073 | AN29: 15073 | AO29: 553 | AP29: 1800 | AR29: 19353 | AS29: 0 | AT29: 0 | AV29: 0 | AY29: 0 | AZ29: Y
A30: 1057 | B30: Ashish V Kumar | C30: M | D30: 101744660729 | E30: Union Bank | F30: 520101001707538 | G30: UBIN0930881 | I30: 30 | J30: 30 | K30: 1.5 | L30: 3 | M30: 0 | N30: 0 | O30: 4.5 | P30: 30 | Q30: 15000 | R30: 1800 | S30: 0 | T30: 0 | U30: 1000 | V30: 1000 | W30: 18800 | X30: 15000 | Y30: 1800 | Z30: 0 | AA30: 0 | AF30: 0 | AG30: 1800 | AH30: 0 | AI30: 126 | AK30: 16800 | AL30: 1926 | AM30: 14874 | AN30: 14874 | AO30: 546 | AP30: 1800 | AR30: 19146 | AS30: 0 | AT30: 0 | AV30: 0 | AY30: 0 | AZ30: Y
A31: 1058 | B31: Shwan Prajwal DSouza | C31: M | D31: 101729961853 | E31: Canara Bank | F31: 3448101002990 | G31: CNRB0003448 | I31: 30 | J31: 30 | K31: 2 | L31: 3 | M31: 0.5 | N31: 0 | O31: 4.5 | P31: 30 | Q31: 15000 | R31: 1800 | S31: 0 | T31: 0 | U31: 1000 | V31: 1000 | W31: 18800 | X31: 15000 | Y31: 1800 | Z31: 0 | AA31: 0 | AF31: 0 | AG31: 1800 | AH31: 0 | AI31: 126 | AK31: 16800 | AL31: 1926 | AM31: 14874 | AN31: 14874 | AO31: 546 | AP31: 1800 | AR31: 19146 | AS31: 0 | AT31: 0 | AV31: 0 | AY31: 0 | AZ31: Y
A32: 1059 | B32: Rajesh Gowda | C32: M | E32: Axis Bank | F32: 404010100044970 | G32: UTIB0000404 | I32: 21 | J32: 14 | K32: 2 | L32: 1 | M32: 2 | N32: 0 | O32: 1 | P32: 14 | Q32: 90000 | W32: 90000 | X32: 60000 | Y32: 0 | Z32: 0 | AA32: 0 | AB32: 0 | AC32: 0 | AF32: 0 | AG32: 0 | AH32: 0 | AI32: 0 | AK32: 60000 | AL32: 6000 | AM32: 60000 | AN32: 54000 | AO32: 0 | AP32: 0 | AR32: 60000 | AS32: 0 | AT32: 0 | AU32: 6000 | AV32: 0 | AW32: 6000 | AY32: 0 | AZ32: Y
A33: 1062 | B33: Shashank Rai | C33: M | E33: Bank of Baroda | F33: 70670100003120 | G33: BARB0VJSHIS | I33: 30 | J33: 30 | K33: 0 | L33: 3 | M33: 1 | N33: 0 | O33: 2 | P33: 30 | Q33: 15000 | R33: 1500 | U33: 1000 | V33: 1000 | W33: 18500 | X33: 15000 | Y33: 1500 | Z33: 0 | AA33: 0 | AF33: 0 | AG33: 0 | AH33: 0 | AI33: 0 | AK33: 16500 | AL33: 0 | AM33: 16500 | AN33: 16500 | AO33: 0 | AP33: 0 | AR33: 16500 | AS33: 0 | AT33: 0 | AV33: 0 | AY33: 0 | AZ33: Y

Sheet May 2025
B1: 45778 | X1: Earnings | AG1: Deductions
A2: Employee ID | B2: Employee Name | C2: Gender | D2: UAN | E2: Bank Name | F2: Bank Account # | G2: Bank IFSC Code | H2: City | I2: Days in month | J2: Days of Pay | K2: Opening Leave Balance | L2: Eligible Leaves | M2: Leaves Availed | N2: Loss of Pay Days | O2: Closing Leave Balance | P2: Payable Days | Q2: Basic + DA | R2: HRA | S2: Medical allowance | T2: Conveyance | U2: Individual Performance Incentive | V2: Company Performance Incentive | W2: Total Fixed Salary | X2: Payable Basic + DA | Y2: Payable HRA | Z2: Payable Medical Allowance | AA2: Payable Conveyance | AB2: Individual Performance Incentive | AC2: Company Performance Incentive | AD2: Salary Loan availed this month | AE2: Other Arrears / Incentives | AF2: Bonus Accrued | AG2: Provident Fund (PF) | AH2: Professional Tax (PT) | AI2: Employees' State Insurance (ESI) | AJ2: Loan EMI | AK2: Total Additions | AL2: Total Deductions | AM2: Total Salary | AN2: Payable Salary | AO2: Employer contribution to ESI | AP2: Employer contribution to PF | AQ2: Gratuity | AR2: Total CTC | AS2: Previous Loan Balance | AT2: Closing Loan Balance | AU2: Tax Deduction on Source (TDS) | AV2: Annual Bonus | AW2: Cumulative TDS for this FY | AX2: Remarks | AY2: Loan repayment outside Salary | AZ2: Active (Y/N)
A3: 1 | B3: =VLOOKUP(A3,#REF!,2,FALSE) -> #REF! | C3: =VLOOKUP(A3,#REF!,19,FALSE) -> #REF! | D3: =VLOOKUP(A3,#REF!,8,FALSE) -> #REF! | E3: =VLOOKUP(A3,#REF!,10,FALSE) -> #REF! | F3: =VLOOKUP(A3,#REF!,11,FALSE) -> #REF! | G3: =VLOOKUP(A3,#REF!,12,FALSE) -> #REF! | I3: 31 | J3: 31 | K3: ='Apr 2025'!O3 -> 11 | L3: 0 | M3: 0 | N3: =IF(K3+L3-M3 >= 0,0,M3-(K3+L3)) -> 0 | O3: =IF(K3+L3-M3>0,K3+L3-M3,0) -> 11 | P3: =J3-N3 -> 31 | Q3: 30000 | R3: 12500 | S3: 5000 | T3: 7500 | U3: 0 | V3: 40000 | W3: =SUM(Q3:V3) -> 95000 | X3: =(Q3/I3*(J3)) * (1-N3/J3) -> 30000 | Y3: =(R3/I3*(J3)) * (1-N3/J3) -> 12500 | Z3: =(S3/I3*(J3)) * (1-N3/J3) -> 5000 | AA3: =(T3/I3*(J3)) * (1-N3/J3) -> 7500 | AC3: =V3*0.7 -> 28000 | AF3: 0 | AG3: =IF(X3>15000,(15000 * 12%),X3*0.12) -> 1800 | AH3: =IF(SUM(X3:AC3)>=25000, 200, 0) -> 200 | AI3: =IF(SUM(Q3:T3) < 21000, SUM(X3:AA3)*0.0075, 0) -> 0 | AK3: =SUM(X3:AF3) -> 83000 | AL3: =SUM(AG3:AJ3)+AU3 -> 2000 | AM3: =SUM(X3:AF3)-SUM(AG3:AJ3) -> 81000 | AN3: =ROUND(AM3-AF3,0)+AV3-AU3 -> 81000 | AO3: =AI3/0.0075*0.0325 -> 0 | AP3: =AG3 -> 1800 | AR3: =AK3+AO3+AP3 -> 84800 | AS3: ='Apr 2025'!AT3 -> 0 | AT3: =AS3+AD3-AJ3 -> 0 | AV3: =AF3*12 -> 0 | AW3: =AU3 -> 0 | AY3: 0 | AZ3: Y
A4: 2 | B4: =VLOOKUP(A4,#REF!,2,FALSE) -> #REF! | C4: =VLOOKUP(A4,#REF!,19,FALSE) -> #REF! | D4: =VLOOKUP(A4,#REF!,8,FALSE) -> #REF! | E4: =VLOOKUP(A4,#REF!,10,FALSE) -> #REF! | F4: =VLOOKUP(A4,#REF!,11,FALSE) -> #REF! | G4: =VLOOKUP(A4,#REF!,12,FALSE) -> #REF! | I4: 31 | J4: 31 | K4: ='Apr 2025'!O4 -> 11 | L4: 0 | M4: 0 | N4: =IF(K4+L4-M4 >= 0,0,M4-(K4+L4)) -> 0 | O4: =IF(K4+L4-M4>0,K4+L4-M4,0) -> 11 | P4: =J4-N4 -> 31 | Q4: 30000 | R4: 12500 | S4: 5000 | T4: 7500 | U4: 0 | V4: 40000 | W4: =SUM(Q4:V4) -> 95000 | X4: =(Q4/I4*(J4)) * (1-N4/J4) -> 30000 | Y4: =(R4/I4*(J4)) * (1-N4/J4) -> 12500 | Z4: =(S4/I4*(J4)) * (1-N4/J4) -> 5000 | AA4: =(T4/I4*(J4)) * (1-N4/J4) -> 7500 | AC4: =V4*0.7 -> 28000 | AF4: 0 | AG4: =IF(X4>15000,(15000 * 12%),X4*0.12) -> 1800 | AH4: =IF(SUM(X4:AC4)>=25000, 200, 0) -> 200 | AI4: =IF(SUM(Q4:T4) < 21000, SUM(X4:AA4)*0.0075, 0) -> 0 | AK4: =SUM(X4:AF4) -> 83000 | AL4: =SUM(AG4:AJ4)+AU4 -> 2000 | AM4: =SUM(X4:AF4)-SUM(AG4:AJ4) -> 81000 | AN4: =ROUND(AM4-AF4,0)+AV4-AU4 -> 81000 | AO4: =AI4/0.0075*0.0325 -> 0 | AP4: =AG4 -> 1800 | AR4: =AK4+AO4+AP4 -> 84800 | AS4: ='Apr 2025'!AT4 -> 0 | AT4: =AS4+AD4-AJ4 -> 0 | AV4: =AF4*12 -> 0 | AW4: =AU4 -> 0 | AY4: 0 | AZ4: Y
A5: 1001 | B5: =VLOOKUP(A5,#REF!,2,FALSE) -> #REF! | C5: =VLOOKUP(A5,#REF!,19,FALSE) -> #REF! | D5: =VLOOKUP(A5,#REF!,8,FALSE) -> #REF! | E5: =VLOOKUP(A5,#REF!,10,FALSE) -> #REF! | F5: =VLOOKUP(A5,#REF!,11,FALSE) -> #REF! | G5: =VLOOKUP(A5,#REF!,12,FALSE) -> #REF! | I5: 31 | J5: 31 | K5: ='Apr 2025'!O5 -> 2.5 | L5: 0 | M5: 1 | N5: =IF(K5+L5-M5 >= 0,0,M5-(K5+L5)) -> 0 | O5: =IF(K5+L5-M5>0,K5+L5-M5,0) -> 1.5 | P5: =J5-N5 -> 31 | Q5: 15000 | R5: 3540 | S5: 1180 | T5: 1180 | U5: 2123 | V5: 2123 | W5: =SUM(Q5:V5) -> 25146 | X5: =(Q5/I5*(J5)) * (1-N5/J5) -> 15000 | Y5: =(R5/I5*(J5)) * (1-N5/J5) -> 3540 | Z5: =(S5/I5*(J5)) * (1-N5/J5) -> 1180 | AA5: =(T5/I5*(J5)) * (1-N5/J5) -> 1180 | AD5: 0 | AF5: 2277 | AG5: =IF(X5>15000,(15000 * 12%),X5*0.12) -> 1800 | AH5: =IF(SUM(X5:AA5)>=25000, 200, 0) -> 0 | AI5: =IF(SUM(Q5:T5) < 21000, SUM(X5:AA5)*0.75%, 0) -> 156.75 | AJ5: 3000 | AK5: =SUM(X5:AF5)-AD5 -> 23177 | AL5: =SUM(AG5:AJ5)+AU5 -> 4956.75 | AM5: =SUM(X5:AF5)-SUM(AG5:AJ5)-AD5 -> 18220.25 | AN5: =ROUND(AM5-AF5,0)-AU5 -> 15943 | AO5: =AI5/0.0075*0.0325 -> 679.25 | AP5: =AG5/0.12*0.13 -> 1950 | AR5: =AK5+AO5+AP5 -> 25806.25 | AS5: ='Apr 2025'!AT5 -> 160000 | AT5: =AS5+AD5-AJ5-AY5 -> 157000 | AV5: 2277 | AW5: =AU5 -> 0 | AY5: 0 | AZ5: Y
A6: 1006 | B6: =VLOOKUP(A6,#REF!,2,FALSE) -> #REF! | C6: =VLOOKUP(A6,#REF!,19,FALSE) -> #REF! | D6: =VLOOKUP(A6,#REF!,8,FALSE) -> #REF! | E6: =VLOOKUP(A6,#REF!,10,FALSE) -> #REF! | F6: =VLOOKUP(A6,#REF!,11,FALSE) -> #REF! | G6: =VLOOKUP(A6,#REF!,12,FALSE) -> #REF! | I6: 31 | J6: 31 | K6: ='Apr 2025'!O6 -> 4.5 | L6: 0 | M6: 1.5 | N6: =IF(K6+L6-M6 >= 0,0,M6-(K6+L6)) -> 0 | O6: =IF(K6+L6-M6>0,K6+L6-M6,0) -> 3 | P6: =J6-N6 -> 31 | Q6: 15000 | R6: 3540 | S6: 1180 | T6: 1180 | U6: 2668 | V6: 2668 | W6: =SUM(Q6:V6) -> 26236 | X6: =(Q6/I6*(J6)) * (1-N6/J6) -> 15000 | Y6: =(R6/I6*(J6)) * (1-N6/J6) -> 3540 | Z6: =(S6/I6*(J6)) * (1-N6/J6) -> 1180 | AA6: =(T6/I6*(J6)) * (1-N6/J6) -> 1180 | AD6: 0 | AF6: 2390 | AG6: =IF(X6>15000,(15000 * 12%),X6*0.12) -> 1800 | AH6: =IF(SUM(X6:AA6)>=25000, 200, 0) -> 0 | AI6: =IF(SUM(Q6:T6) < 21000, SUM(X6:AA6)*0.75%, 0) -> 156.75 | AJ6: 0 | AK6: =SUM(X6:AF6)-AD6 -> 23290 | AL6: =SUM(AG6:AJ6)+AU6 -> 1956.75 | AM6: =SUM(X6:AF6)-SUM(AG6:AJ6)-AD6 -> 21333.25 | AN6: =ROUND(AM6-AF6,0)-AU6 -> 18943 | AO6: =AI6/0.0075*0.0325 -> 679.25 | AP6: =AG6/0.12*0.13 -> 1950 | AR6: =AK6+AO6+AP6 -> 25919.25 | AS6: ='Apr 2025'!AT6 -> 185000 | AT6: =AS6+AD6-AJ6-AY6 -> 0 | AV6: 2390 | AW6: =AU6 -> 0 | AY6: 185000 | AZ6: Y
A7: 1024 | B7: =VLOOKUP(A7,#REF!,2,FALSE) -> #REF! | C7: =VLOOKUP(A7,#REF!,19,FALSE) -> #REF! | D7: =VLOOKUP(A7,#REF!,8,FALSE) -> #REF! | E7: =VLOOKUP(A7,#REF!,10,FALSE) -> #REF! | F7: =VLOOKUP(A7,#REF!,11,FALSE) -> #REF! | G7: =VLOOKUP(A7,#REF!,12,FALSE) -> #REF! | I7: 31 | J7: 31 | K7: ='Apr 2025'!O7 -> 4 | L7: 0 | M7: 2 | N7: =IF(K7+L7-M7 >= 0,0,M7-(K7+L7)) -> 0 | O7: =IF(K7+L7-M7>0,K7+L7-M7,0) -> 2 | P7: =J7-N7 -> 31 | Q7: 15000 | R7: 2388 | S7: 796 | T7: 796 | U7: 500 | V7: 500 | W7: =SUM(Q7:V7) -> 19980 | X7: =(Q7/I7*(J7)) * (1-N7/J7) -> 15000 | Y7: =(R7/I7*(J7)) * (1-N7/J7) -> 2388 | Z7: =(S7/I7*(J7)) * (1-N7/J7) -> 796 | AA7: =(T7/I7*(J7)) * (1-N7/J7) -> 796 | AF7: 1823 | AG7: =IF(X7>15000,(15000 * 12%),X7*0.12) -> 1800 | AH7: =IF(SUM(X7:AA7)>=25000, 200, 0) -> 0 | AI7: =IF(SUM(Q7:T7) < 21000, SUM(X7:AA7)*0.0075, 0) -> 142.35 | AJ7: 2000 | AK7: =SUM(X7:AF7) -> 20803 | AL7: =SUM(AG7:AJ7)+AU7 -> 3942.35 | AM7: =SUM(X7:AF7)-SUM(AG7:AJ7) -> 16860.65 | AN7: =ROUND(AM7-AF7,0)-AU7 -> 15038 | AO7: =AI7/0.0075*0.0325 -> 616.85 | AP7: =AG7 -> 1800 | AR7: =AK7+AO7+AP7 -> 23219.85 | AS7: ='Apr 2025'!AT7 -> 19500 | AT7: =AS7+AD7-AJ7-AY7 -> 0 | AV7: 1823 | AW7: =AU7 -> 0 | AY7: 17500 | AZ7: Y
A8: 1028 | B8: =VLOOKUP(A8,#REF!,2,FALSE) -> #REF! | C8: =VLOOKUP(A8,#REF!,19,FALSE) -> #REF! | D8: =VLOOKUP(A8,#REF!,8,FALSE) -> #REF! | E8: =VLOOKUP(A8,#REF!,10,FALSE) -> #REF! | F8: =VLOOKUP(A8,#REF!,11,FALSE) -> #REF! | G8: =VLOOKUP(A8,#REF!,12,FALSE) -> #REF! | I8: 31 | J8: 31 | K8: ='Apr 2025'!O8 -> 2 | L8: 0 | M8: 2 | N8: =IF(K8+L8-M8 >= 0,0,M8-(K8+L8)) -> 0 | O8: =IF(K8+L8-M8>0,K8+L8-M8,0) -> 0 | P8: =J8-N8 -> 31 | Q8: 15000 | R8: 7000 | S8: 6000 | T8: 5000 | U8: 5000 | V8: 5000 | W8: =SUM(Q8:V8) -> 43000 | X8: =(Q8/I8*(J8)) * (1-N8/J8) -> 15000 | Y8: =(R8/I8*(J8)) * (1-N8/J8) -> 7000 | Z8: =(S8/I8*(J8)) * (1-N8/J8) -> 6000 | AA8: =(T8/I8*(J8)) * (1-N8/J8) -> 5000 | AB8: =U8*1 -> 5000 | AC8: =V8*0.7 -> 3500 | AF8: 0 | AG8: =IF(X8>15000,(15000 * 12%),X8*0.12) -> 1800 | AH8: =IF(SUM(X8:AA8)>=25000, 200, 0) -> 200 | AI8: =IF(SUM(Q8:T8) < 21000, SUM(X8:AA8)*0.0075, 0) -> 0 | AK8: =SUM(X8:AF8) -> 41500 | AL8: =SUM(AG8:AJ8)+AU8 -> 2000 | AM8: =SUM(X8:AF8)-SUM(AG8:AJ8) -> 39500 | AN8: =ROUND(AM8-AF8,0)+AV8-AU8 -> 39500 | AO8: =AI8/0.0075*0.0325 -> 0 | AP8: =AG8 -> 1800 | AR8: =AK8+AO8+AP8 -> 43300 | AS8: ='Apr 2025'!AT8 -> 0 | AT8: =AS8+AD8-AJ8-AY8 -> 0 | AV8: =AF8*12 -> 0 | AW8: =AU8 -> 0 | AY8: 0 | AZ8: Y
A9: 1030 | B9: =VLOOKUP(A9,#REF!,2,FALSE) -> #REF! | C9: =VLOOKUP(A9,#REF!,19,FALSE) -> #REF! | D9: =VLOOKUP(A9,#REF!,8,FALSE) -> #REF! | E9: =VLOOKUP(A9,#REF!,10,FALSE) -> #REF! | F9: =VLOOKUP(A9,#REF!,11,FALSE) -> #REF! | G9: =VLOOKUP(A9,#REF!,12,FALSE) -> #REF! | I9: 31 | J9: 31 | K9: ='Apr 2025'!O9 -> 3 | L9: 0 | M9: 3 | N9: =IF(K9+L9-M9 >= 0,0,M9-(K9+L9)) -> 0 | O9: =IF(K9+L9-M9>0,K9+L9-M9,0) -> 0 | P9: =J9-N9 -> 31 | Q9: 15000 | R9: 3540 | S9: 1180 | T9: 1180 | U9: 2150 | V9: 2150 | W9: =SUM(Q9:V9) -> 25200 | X9: =(Q9/I9*(J9)) * (1-N9/J9) -> 15000 | Y9: =(R9/I9*(J9)) * (1-N9/J9) -> 3540 | Z9: =(S9/I9*(J9)) * (1-N9/J9) -> 1180 | AA9: =(T9/I9*(J9)) * (1-N9/J9) -> 1180 | AF9: 0 | AG9: =IF(X9>15000,(15000 * 12%),X9*0.12) -> 1800 | AH9: =IF(SUM(X9:AA9)>=25000, 200, 0) -> 0 | AI9: =IF(SUM(Q9:T9) < 21000, SUM(X9:AA9)*0.0075, 0) -> 156.75 | AK9: =SUM(X9:AF9) -> 20900 | AL9: =SUM(AG9:AJ9)+AU9 -> 1956.75 | AM9: =SUM(X9:AF9)-SUM(AG9:AJ9) -> 18943.25 | AN9: =ROUND(AM9-AF9,0)+AV9-AU9 -> 18943 | AO9: =AI9/0.0075*0.0325 -> 679.25 | AP9: =AG9 -> 1800 | AR9: =AK9+AO9+AP9 -> 23379.25 | AS9: ='Apr 2025'!AT9 -> 0 | AT9: =AS9+AD9-AJ9-AY9 -> 0 | AV9: =AF9*12 -> 0 | AW9: =AU9 -> 0 | AY9: 0 | AZ9: Y
A10: 1031 | B10: =VLOOKUP(A10,#REF!,2,FALSE) -> #REF! | C10: =VLOOKUP(A10,#REF!,19,FALSE) -> #REF! | D10: =VLOOKUP(A10,#REF!,8,FALSE) -> #REF! | E10: =VLOOKUP(A10,#REF!,10,FALSE) -> #REF! | F10: =VLOOKUP(A10,#REF!,11,FALSE) -> #REF! | G10: =VLOOKUP(A10,#REF!,12,FALSE) -> #REF! | I10: 31 | J10: 31 | K10: ='Apr 2025'!O10 -> 2 | L10: 1 | M10: 2.5 | N10: =IF(K10+L10-M10 >= 0,0,M10-(K10+L10)) -> 0 | O10: =IF(K10+L10-M10>0,K10+L10-M10,0) -> 0.5 | P10: =J10-N10 -> 31 | Q10: 15000 | R10: 9000 | S10: 8000 | T10: 3000 | U10: 6000 | V10: 6000 | W10: =SUM(Q10:V10) -> 47000 | X10: =(Q10/I10*(J10)) * (1-N10/J10) -> 15000 | Y10: =(R10/I10*(J10)) * (1-N10/J10) -> 9000 | Z10: =(S10/I10*(J10)) * (1-N10/J10) -> 8000 | AA10: =(T10/I10*(J10)) * (1-N10/J10) -> 3000 | AB10: =U10*1.2 -> 7200 | AC10: =V10*0.7 -> 4200 | AF10: 0 | AG10: =IF(X10>15000,(15000 * 12%),X10*0.12) -> 1800 | AH10: =IF(SUM(X10:AC10)>=25000, 200, 0) -> 200 | AI10: 0 | AK10: =SUM(X10:AF10) -> 46400 | AL10: =SUM(AG10:AJ10)+AU10 -> 2000 | AM10: =SUM(X10:AF10)-SUM(AG10:AJ10) -> 44400 | AN10: =ROUND(AM10-AF10,0)+AV10-AU10 -> 44400 | AO10: =AI10/0.0075*0.0325 -> 0 | AP10: =AG10 -> 1800 | AR10: =AK10+AO10+AP10 -> 48200 | AS10: ='Apr 2025'!AT10 -> 0 | AT10: =AS10+AD10-AJ10-AY10 -> 0 | AV10: =AF10*12 -> 0 | AW10: =AU10 -> 0 | AY10: 0 | AZ10: Y
A11: 1033 | B11: =VLOOKUP(A11,#REF!,2,FALSE) -> #REF! | C11: =VLOOKUP(A11,#REF!,19,FALSE) -> #REF! | D11: =VLOOKUP(A11,#REF!,8,FALSE) -> #REF! | E11: =VLOOKUP(A11,#REF!,10,FALSE) -> #REF! | F11: =VLOOKUP(A11,#REF!,11,FALSE) -> #REF! | G11: =VLOOKUP(A11,#REF!,12,FALSE) -> #REF! | I11: 31 | J11: 31 | K11: ='Apr 2025'!O11 -> 1 | L11: 0 | M11: 23 | N11: =IF(K11+L11-M11 >= 0,0,M11-(K11+L11)) -> 22 | O11: =IF(K11+L11-M11>0,K11+L11-M11,0) -> 0 | P11: =J11-N11 -> 9 | Q11: 15000 | R11: 3540 | S11: 1180 | T11: 1180 | U11: 550 | V11: 550 | W11: =SUM(Q11:V11) -> 22000 | X11: =(Q11/I11*(J11)) * (1-N11/J11) -> 4354.8387 | Y11: =(R11/I11*(J11)) * (1-N11/J11) -> 1027.7419 | Z11: =(S11/I11*(J11)) * (1-N11/J11) -> 342.58065 | AA11: =(T11/I11*(J11)) * (1-N11/J11) -> 342.58065 | AF11: 0 | AG11: =IF(X11>15000,(15000 * 12%),X11*0.12) -> 522.58065 | AH11: =IF(SUM(X11:AA11)>=25000, 200, 0) -> 0 | AI11: =IF(SUM(Q11:T11) < 21000, SUM(X11:AA11)*0.0075, 0) -> 45.508065 | AK11: =SUM(X11:AF11) -> 6067.7419 | AL11: =SUM(AG11:AJ11)+AU11 -> 568.08871 | AM11: =SUM(X11:AF11)-SUM(AG11:AJ11) -> 5499.6532 | AN11: =ROUND(AM11-AF11,0)+AV11-AU11 -> 5500 | AO11: =AI11/0.0075*0.0325 -> 197.20161 | AP11: =AG11 -> 522.58065 | AR11: =AK11+AO11+AP11 -> 6787.5242 | AS11: ='Apr 2025'!AT11 -> 0 | AT11: =AS11+AD11-AJ11-AY11 -> 0 | AV11: =AF11*12 -> 0 | AW11: =AU11 -> 0 | AY11: 0 | AZ11: Y
A12: 1034 | B12: =VLOOKUP(A12,#REF!,2,FALSE) -> #REF! | C12: =VLOOKUP(A12,#REF!,19,FALSE) -> #REF! | D12: =VLOOKUP(A12,#REF!,8,FALSE) -> #REF! | E12: =VLOOKUP(A12,#REF!,10,FALSE) -> #REF! | F12: =VLOOKUP(A12,#REF!,11,FALSE) -> #REF! | G12: =VLOOKUP(A12,#REF!,12,FALSE) -> #REF! | I12: 31 | J12: 31 | K12: ='Apr 2025'!O12 -> 0 | L12: 0 | M12: 2 | N12: =IF(K12+L12-M12 >= 0,0,M12-(K12+L12)) -> 2 | O12: =IF(K12+L12-M12>0,K12+L12-M12,0) -> 0 | P12: =J12-N12 -> 29 | Q12: 15000 | R12: 3540 | S12: 1180 | T12: 1180 | U12: 2050 | V12: 2050 | W12: =SUM(Q12:V12) -> 25000 | X12: =(Q12/I12*(J12)) * (1-N12/J12) -> 14032.258 | Y12: =(R12/I12*(J12)) * (1-N12/J12) -> 3311.6129 | Z12: =(S12/I12*(J12)) * (1-N12/J12) -> 1103.871 | AA12: =(T12/I12*(J12)) * (1-N12/J12) -> 1103.871 | AF12: 0 | AG12: =IF(X12>15000,(15000 * 12%),X12*0.12) -> 1683.871 | AH12: =IF(SUM(X12:AA12)>=25000, 200, 0) -> 0 | AI12: =IF(SUM(Q12:T12) < 21000, SUM(X12:AA12)*0.0075, 0) -> 146.6371 | AK12: =SUM(X12:AF12) -> 19551.613 | AL12: =SUM(AG12:AJ12)+AU12 -> 1830.5081 | AM12: =SUM(X12:AF12)-SUM(AG12:AJ12) -> 17721.105 | AN12: =ROUND(AM12-AF12,0)+AV12-AU12 -> 17721 | AO12: =AI12/0.0075*0.0325 -> 635.42742 | AP12: =AG12 -> 1683.871 | AR12: =AK12+AO12+AP12 -> 21870.911 | AS12: ='Apr 2025'!AT12 -> 0 | AT12: =AS12+AD12-AJ12-AY12 -> 0 | AV12: =AF12*12 -> 0 | AW12: =AU12 -> 0 | AY12: 0 | AZ12: Y
A13: 1036 | B13: =VLOOKUP(A13,#REF!,2,FALSE) -> #REF! | C13: =VLOOKUP(A13,#REF!,19,FALSE) -> #REF! | D13: =VLOOKUP(A13,#REF!,8,FALSE) -> #REF! | E13: =VLOOKUP(A13,#REF!,10,FALSE) -> #REF! | F13: =VLOOKUP(A13,#REF!,11,FALSE) -> #REF! | G13: =VLOOKUP(A13,#REF!,12,FALSE) -> #REF! | I13: 31 | J13: 31 | K13: ='Apr 2025'!O13 -> 0 | L13: 0 | M13: 3 | N13: =IF(K13+L13-M13 >= 0,0,M13-(K13+L13)) -> 3 | O13: =IF(K13+L13-M13>0,K13+L13-M13,0) -> 0 | P13: =J13-N13 -> 28 | Q13: 15000 | R13: 3540 | S13: 1180 | T13: 1180 | U13: 2200 | V13: 2200 | W13: =SUM(Q13:V13) -> 25300 | X13: =(Q13/I13*(J13)) * (1-N13/J13) -> 13548.387 | Y13: =(R13/I13*(J13)) * (1-N13/J13) -> 3197.4194 | Z13: =(S13/I13*(J13)) * (1-N13/J13) -> 1065.8065 | AA13: =(T13/I13*(J13)) * (1-N13/J13) -> 1065.8065 | AF13: 0 | AG13: =IF(X13>15000,(15000 * 12%),X13*0.12) -> 1625.8065 | AH13: =IF(SUM(X13:AA13)>=25000, 200, 0) -> 0 | AI13: =IF(SUM(Q13:T13) < 21000, SUM(X13:AA13)*0.0075, 0) -> 141.58065 | AK13: =SUM(X13:AF13) -> 18877.419 | AL13: =SUM(AG13:AJ13)+AU13 -> 1767.3871 | AM13: =SUM(X13:AF13)-SUM(AG13:AJ13) -> 17110.032 | AN13: =ROUND(AM13-AF13,0)+AV13-AU13 -> 17110 | AO13: =AI13/0.0075*0.0325 -> 613.51613 | AP13: =AG13 -> 1625.8065 | AR13: =AK13+AO13+AP13 -> 21116.742 | AS13: ='Apr 2025'!AT13 -> 0 | AT13: =AS13+AD13-AJ13-AY13 -> 0 | AV13: =AF13*12 -> 0 | AW13: =AU13 -> 0 | AY13: 0 | AZ13: Y
A14: 1037 | B14: =VLOOKUP(A14,#REF!,2,FALSE) -> #REF! | C14: =VLOOKUP(A14,#REF!,19,FALSE) -> #REF! | D14: =VLOOKUP(A14,#REF!,8,FALSE) -> #REF! | E14: =VLOOKUP(A14,#REF!,10,FALSE) -> #REF! | F14: =VLOOKUP(A14,#REF!,11,FALSE) -> #REF! | G14: =VLOOKUP(A14,#REF!,12,FALSE) -> #REF! | I14: 31 | J14: 31 | K14: ='Apr 2025'!O14 -> 2.5 | L14: 0 | M14: 2 | N14: =IF(K14+L14-M14 >= 0,0,M14-(K14+L14)) -> 0 | O14: =IF(K14+L14-M14>0,K14+L14-M14,0) -> 0.5 | P14: =J14-N14 -> 31 | Q14: 26000 | R14: 14808 | S14: 11106 | T14: 11106 | U14: 5395 | V14: 5395 | W14: =SUM(Q14:V14) -> 73810 | X14: =(Q14/I14*(J14)) * (1-N14/J14) -> 26000 | Y14: =(R14/I14*(J14)) * (1-N14/J14) -> 14808 | Z14: =(S14/I14*(J14)) * (1-N14/J14) -> 11106 | AA14: =(T14/I14*(J14)) * (1-N14/J14) -> 11106 | AB14: =U14*0.8 -> 4316 | AC14: =V14*0.7 -> 3776.5 | AF14: 0 | AG14: =IF(X14>15000,(15000 * 12%),X14*0.12) -> 1800 | AH14: =IF(SUM(X14:AC14)>=25000, 200, 0) -> 200 | AI14: =IF(SUM(Q14:T14) < 21000, SUM(X14:AA14)*0.0075, 0) -> 0 | AK14: =SUM(X14:AF14) -> 71112.5 | AL14: =SUM(AG14:AJ14)+AU14 -> 2000 | AM14: =SUM(X14:AF14)-SUM(AG14:AJ14) -> 69112.5 | AN14: =ROUND(AM14-AF14,0)+AV14-AU14 -> 69113 | AO14: =AI14/0.0075*0.0325 -> 0 | AP14: =AG14 -> 1800 | AR14: =AK14+AO14+AP14 -> 72912.5 | AS14: ='Apr 2025'!AT14 -> 0 | AT14: =AS14+AD14-AJ14-AY14 -> 0 | AV14: =AF14*12 -> 0 | AW14: =AU14 -> 0 | AY14: 0 | AZ14: Y
A15: 1042 | B15: =VLOOKUP(A15,#REF!,2,FALSE) -> #REF! | C15: =VLOOKUP(A15,#REF!,19,FALSE) -> #REF! | D15: =VLOOKUP(A15,#REF!,8,FALSE) -> #REF! | E15: =VLOOKUP(A15,#REF!,10,FALSE) -> #REF! | F15: =VLOOKUP(A15,#REF!,11,FALSE) -> #REF! | G15: =VLOOKUP(A15,#REF!,12,FALSE) -> #REF! | I15: 31 | J15: 31 | K15: ='Apr 2025'!O15 -> 6 | L15: 0 | M15: 1 | N15: =IF(K15+L15-M15 >= 0,0,M15-(K15+L15)) -> 0 | O15: =IF(K15+L15-M15>0,K15+L15-M15,0) -> 5 | P15: =J15-N15 -> 31 | Q15: 30000 | R15: 17040 | S15: 12780 | T15: 12780 | U15: 6600 | V15: 6600 | W15: =SUM(Q15:V15) -> 85800 | X15: =(Q15/I15*(J15)) * (1-N15/J15) -> 30000 | Y15: =(R15/I15*(J15)) * (1-N15/J15) -> 17040 | Z15: =(S15/I15*(J15)) * (1-N15/J15) -> 12780 | AA15: =(T15/I15*(J15)) * (1-N15/J15) -> 12780 | AB15: =U15*1 -> 6600 | AC15: =V15*0.7 -> 4620 | AF15: 0 | AG15: =IF(X15>15000,(15000 * 12%),X15*0.12) -> 1800 | AH15: =IF(SUM(X15:AC15)>=25000, 200, 0) -> 200 | AI15: 0 | AK15: =SUM(X15:AF15) -> 83820 | AL15: =SUM(AG15:AJ15)+AU15 -> 2000 | AM15: =SUM(X15:AF15)-SUM(AG15:AJ15) -> 81820 | AN15: =ROUND(AM15-AF15,0)+AV15-AU15 -> 81820 | AO15: 0 | AP15: =AG15 -> 1800 | AR15: =AK15+AO15+AP15 -> 85620 | AS15: ='Apr 2025'!AT15 -> 0 | AT15: =AS15+AD15-AJ15-AY15 -> 0 | AV15: =AF15*12 -> 0 | AW15: =AU15 -> 0 | AY15: 0 | AZ15: Y
A16: 1044 | B16: =VLOOKUP(A16,#REF!,2,FALSE) -> #REF! | C16: =VLOOKUP(A16,#REF!,19,FALSE) -> #REF! | D16: =VLOOKUP(A16,#REF!,8,FALSE) -> #REF! | E16: =VLOOKUP(A16,#REF!,10,FALSE) -> #REF! | F16: =VLOOKUP(A16,#REF!,11,FALSE) -> #REF! | G16: =VLOOKUP(A16,#REF!,12,FALSE) -> #REF! | I16: 31 | J16: 31 | K16: ='Apr 2025'!O16 -> 0 | L16: 0 | M16: 2 | N16: =IF(K16+L16-M16 >= 0,0,M16-(K16+L16)) -> 2 | O16: =IF(K16+L16-M16>0,K16+L16-M16,0) -> 0 | P16: =J16-N16 -> 29 | Q16: 26000 | R16: 11600 | S16: 8700 | T16: 8700 | U16: 0 | V16: 27500 | W16: =SUM(Q16:V16) -> 82500 | X16: =(Q16/I16*(J16)) * (1-N16/J16) -> 24322.581 | Y16: =(R16/I16*(J16)) * (1-N16/J16) -> 10851.613 | Z16: =(S16/I16*(J16)) * (1-N16/J16) -> 8138.7097 | AA16: =(T16/I16*(J16)) * (1-N16/J16) -> 8138.7097 | AB16: =U16*1 -> 0 | AC16: =V16*0.7 -> 19250 | AF16: 0 | AG16: =IF(X16>15000,(15000 * 12%),X16*0.12) -> 1800 | AH16: =IF(SUM(X16:AC16)>=25000, 200, 0) -> 200 | AI16: =IF(SUM(Q16:T16) < 21000, SUM(X16:AA16)*0.0075, 0) -> 0 | AK16: =SUM(X16:AF16) -> 70701.613 | AL16: =SUM(AG16:AJ16)+AU16 -> 2000 | AM16: =SUM(X16:AF16)-SUM(AG16:AJ16) -> 68701.613 | AN16: =ROUND(AM16-AF16,0)+AV16-AU16 -> 68702 | AO16: =AI16/0.0075*0.0325 -> 0 | AP16: =AG16 -> 1800 | AR16: =AK16+AO16+AP16 -> 72501.613 | AS16: ='Apr 2025'!AT16 -> 0 | AT16: =AS16+AD16-AJ16-AY16 -> 0 | AV16: =AF16*12 -> 0 | AW16: =AU16 -> 0 | AY16: 0 | AZ16: Y
A17: 1047 | B17: =VLOOKUP(A17,#REF!,2,FALSE) -> #REF! | C17: =VLOOKUP(A17,#REF!,19,FALSE) -> #REF! | D17: =VLOOKUP(A17,#REF!,8,FALSE) -> #REF! | E17: =VLOOKUP(A17,#REF!,10,FALSE) -> #REF! | F17: =VLOOKUP(A17,#REF!,11,FALSE) -> #REF! | G17: =VLOOKUP(A17,#REF!,12,FALSE) -> #REF! | I17: 31 | J17: 31 | K17: ='Apr 2025'!O17 -> 7.5 | L17: 0 | M17: 1.5 | N17: =IF(K17+L17-M17 >= 0,0,M17-(K17+L17)) -> 0 | O17: =IF(K17+L17-M17>0,K17+L17-M17,0) -> 6 | P17: =J17-N17 -> 31 | Q17: 26000 | R17: =225000/12 -> 18750 | S17: =15000/12 -> 1250 | T17: =130000/12 -> 10833.333 | U17: =195000/12/2 -> 8125 | V17: =195000/12/2 -> 8125 | W17: =SUM(Q17:V17) -> 73083.333 | X17: =(Q17/I17*(J17)) * (1-N17/J17) -> 26000 | Y17: =(R17/I17*(J17)) * (1-N17/J17) -> 18750 | Z17: =(S17/I17*(J17)) * (1-N17/J17) -> 1250 | AA17: =(T17/I17*(J17)) * (1-N17/J17) -> 10833.333 | AB17: =U17*1 -> 8125 | AC17: =V17*0.7 -> 5687.5 | AF17: 0 | AG17: =IF(X17>15000,(15000 * 12%),X17*0.12) -> 1800 | AH17: =IF(SUM(X17:AC17)>=25000, 200, 0) -> 200 | AI17: =IF(SUM(Q17:T17) < 21000, SUM(X17:AA17)*0.0075, 0) -> 0 | AK17: =SUM(X17:AF17) -> 70645.833 | AL17: =SUM(AG17:AJ17)+AU17 -> 2000 | AM17: =SUM(X17:AF17)-SUM(AG17:AJ17) -> 68645.833 | AN17: =ROUND(AM17-AF17,0)+AV17-AU17 -> 68646 | AO17: =AI17/0.0075*0.0325 -> 0 | AP17: =AG17 -> 1800 | AR17: =AK17+AO17+AP17 -> 72445.833 | AS17: ='Apr 2025'!AT17 -> 0 | AT17: =AS17+AD17-AJ17-AY17 -> 0 | AV17: =AF17*12 -> 0 | AW17: =AU17 -> 0 | AY17: 0 | AZ17: Y
